Workbook

Sheet README
A1: India Travel Guide & Budget Finder - Dataset (15 destinations)
A2: Compiled 20 Sep 2026 for app development. Read the 'Data quality' section before publishing anything to end users.
A4: PURPOSE
A5: What this is | B5: A structured starter dataset for a travel-guide + budget-finder app covering 15 destinations: New Delhi, Taj Mahal (Agra), Jaipur, Udaipur, Hampi, Ajanta & Ellora, Goa, Kerala Backwaters, Andaman & Nicobar, Pondicherry, Varanasi, Amritsar, Mysore, Leh-Ladakh, Darjeeling.
A6: Key idea | B6: Every destination has multiple options in every category across Budget / Mid-range / Premium / Luxury, so your app can filter by budget. Dest_ID (DEL, AGR, JAI, ...) is the join key across all sheets.
A7: SHEETS
A8: Destinations | B8: One row per destination: state, coordinates, altitude, airport/rail, best/avoid months, ideal days, languages, official info source, and formula-driven per-day budget per person for 3 tiers + counts of records.
A9: Attractions | B9: Monuments, temples, museums, beaches, viewpoints, experiences: fees (Indians/foreigners), timings, closed days, time needed, best time, UNESCO flag, tips, confidence grade.
A10: Hotels | B10: Hostels to palace hotels with Tier, Type, area, indicative price range per room per night.
A11: Restaurants | B11: Iconic eateries, street food, cafes and fine dining; price for two; veg/non-veg; must-try dishes.
A12: Transport | B12: Getting there (flight/train/road) and local transport with duration and indicative cost.
A13: Seasons | B13: Season-wise temperature, rainfall, crowd/price level for each destination.
A14: Month_Grid | B14: Month suitability score 1 (avoid) to 5 (best) per destination, colour-scaled.
A15: Budget_Tiers | B15: INPUT table (blue): per-tier daily cost components per destination. Feeds Destinations and Budget_Estimator.
A16: Budget_Estimator | B16: Interactive calculator: choose destination, tier, days, travellers -> full breakdown + 3-tier comparison (formulas).
A17: Festivals | B17: Major festivals/events by destination (timings approximate; verify yearly).
A18: Practical_Info | B18: Emergency numbers, health/safety, connectivity/cash, dress code, permits and common scams.
A19: Circuits | B19: Multi-destination trip ideas with ideal days and connection notes.
A20: TIER DEFINITIONS
A21: Hotels (per room/night) | B21: Budget: up to Rs2,500 | Mid-range: Rs2,500-7,000 | Premium: Rs7,000-20,000 | Luxury: above Rs20,000 (double occupancy; peak season/festivals can be 1.5-3x).
A22: Restaurants (for two) | B22: Price columns are approximate cost for TWO people before tax/service unless the row says otherwise.
A23: DATA QUALITY (IMPORTANT)
A24: Confidence grades (Attractions) | B24: A = cross-checked against live web sources on 20 Sep 2026 (only the Taj Mahal entry/timing details and Ladakh permit/fee rules); B = standard published information (name, location, typical timings, historically stable fee) - verify before publishing; C = indicative/approximate value (fees that change often, or estimates) - must be verified.
A25: What is reliable | B25: Place names, locations, categories, closed-day patterns, tier assignment, and the overall structure are drawn from well-established public information.
A26: What is NOT guaranteed | B26: Exact ticket prices, timings, hotel/restaurant prices and transport fares change often (ASI revisions, seasons, dynamic pricing). Hotel and restaurant prices are indicative ranges only - not live rates. Some hotel/hostel branches, ferry operators and train schedules may have changed.
A27: Known conflict found | B27: Taj Mahal foreign-tourist fee: the official ASI page lists Rs1,100 (+Rs200 mausoleum) 'inclusive of ASI & ADA fees'; another government page lists an extra Rs500 ADA fee; a third-party site shows Rs1,300. Treat foreign fee as Rs1,100-1,600 until you confirm on the ASI/Agra Development Authority portal.
A28: Before going live | B28: 1) Verify each fee/timing on the official source (see Destinations > Official_Info_Source). 2) Use live APIs for hotel/flight/train prices (e.g., partner APIs, IRCTC). 3) Add Last_Verified and Source_URL columns per row in your database. 4) Re-verify high-change items (fees, closures, ferry/train schedules) each season.
A29: Seasonal caveat | B29: Ladakh roads, Andaman ferries, Goa shacks, Hampi coracles, Dudhsagar jeep trips and several Kerala boats are weather- or season-dependent.
A30: Suggested DB schema | B30: destinations(dest_id PK), attractions(attraction_id PK, dest_id FK), hotels(hotel_id PK, dest_id FK), restaurants(restaurant_id PK, dest_id FK), transport(dest_id FK), seasons(dest_id FK), budget_tiers(dest_id, tier). Add: latitude/longitude per place, images, rating, last_verified, source_url.

Sheet Destinations
A1: Dest_ID | B1: Destination | C1: State / UT | D1: Region | E1: Category | F1: Latitude | G1: Longitude | H1: Altitude (m) | I1: Nearest airport | J1: Nearest railway | K1: Best months | L1: Months to avoid | M1: Ideal days | N1: Languages | O1: Known for | P1: Budget tier: INR/person/day | Q1: Mid-range tier: INR/person/day | R1: Premium tier: INR/person/day | S1: Attractions (count) | T1: Hotels (count) | U1: Restaurants (count) | V1: Official info source (confirm URL)
A2: DEL | B2: New Delhi | C2: Delhi (NCT) | D2: North | E2: City / Heritage / Capital | F2: 28.6139 | G2: 77.209 | H2: 216 | I2: Indira Gandhi Intl (DEL) - 15-20 km | J2: New Delhi (NDLS), Old Delhi (DLI), H. Nizamuddin (NZM) | K2: Oct-Mar (peak Nov-Feb) | L2: May-Jun (extreme heat); Nov-Jan (air pollution / fog) | M2: 3 | N2: Hindi, English, Punjabi, Urdu | O2: Mughal monuments, Lutyens' Delhi, Old Delhi street food, museums, gateway hub for the Golden Triangle | P2: =INDEX(Budget_Tiers!$L$2:$L$46,MATCH($A2&"|Budget",Budget_Tiers!$A$2:$A$46,0)) -> 1750 | Q2: =INDEX(Budget_Tiers!$L$2:$L$46,MATCH($A2&"|Mid-range",Budget_Tiers!$A$2:$A$46,0)) -> 4500 | R2: =INDEX(Budget_Tiers!$L$2:$L$46,MATCH($A2&"|Premium",Budget_Tiers!$A$2:$A$46,0)) -> 11500 | S2: =COUNTIF(Attractions!$B:$B,$A2) -> 12 | T2: =COUNTIF(Hotels!$B:$B,$A2) -> 7 | U2: =COUNTIF(Restaurants!$B:$B,$A2) -> 7 | V2: delhitourism.gov.in; incredibleindia.gov.in; asi.nic.in
A3: AGR | B3: Taj Mahal (Agra) | C3: Uttar Pradesh | D3: North | E3: Heritage / UNESCO | F3: 27.1751 | G3: 78.0421 | H3: 171 | I3: Agra Kheria (AGR) - limited flights; most fly into Delhi (DEL, ~230 km) | J3: Agra Cantt (AGC), Agra Fort (AF), Raja Ki Mandi (RKM) | K3: Oct-Mar | L3: Apr-Jun (up to 45C); Dec-Jan mornings can be foggy (Taj hidden) | M3: 2 | N3: Hindi, English, Braj | O3: Taj Mahal, Agra Fort, Fatehpur Sikri, Mughal food & marble inlay craft | P3: =INDEX(Budget_Tiers!$L$2:$L$46,MATCH($A3&"|Budget",Budget_Tiers!$A$2:$A$46,0)) -> 1750 | Q3: =INDEX(Budget_Tiers!$L$2:$L$46,MATCH($A3&"|Mid-range",Budget_Tiers!$A$2:$A$46,0)) -> 4500 | R3: =INDEX(Budget_Tiers!$L$2:$L$46,MATCH($A3&"|Premium",Budget_Tiers!$A$2:$A$46,0)) -> 10700 | S3: =COUNTIF(Attractions!$B:$B,$A3) -> 8 | T3: =COUNTIF(Hotels!$B:$B,$A3) -> 8 | U3: =COUNTIF(Restaurants!$B:$B,$A3) -> 6 | V3: tajmahal.gov.in; uptourism.gov.in; asi.nic.in
A4: JAI | B4: Jaipur | C4: Rajasthan | D4: North-West | E4: Heritage / City / Shopping | F4: 26.9124 | G4: 75.7873 | H4: 431 | I4: Jaipur Intl (JAI) - 13 km | J4: Jaipur Jn (JP), Gandhinagar Jaipur (GADJ) | K4: Oct-Mar | L4: Apr-Jun (hot); peak monsoon Jul-Aug is humid but green | M4: 3 | N4: Hindi, Rajasthani, English | O4: Pink City, Amber Fort, City Palace, Hawa Mahal, bazaars, block-print & jewellery, Rajasthani cuisine | P4: =INDEX(Budget_Tiers!$L$2:$L$46,MATCH($A4&"|Budget",Budget_Tiers!$A$2:$A$46,0)) -> 1700 | Q4: =INDEX(Budget_Tiers!$L$2:$L$46,MATCH($A4&"|Mid-range",Budget_Tiers!$A$2:$A$46,0)) -> 4200 | R4: =INDEX(Budget_Tiers!$L$2:$L$46,MATCH($A4&"|Premium",Budget_Tiers!$A$2:$A$46,0)) -> 10400 | S4: =COUNTIF(Attractions!$B:$B,$A4) -> 10 | T4: =COUNTIF(Hotels!$B:$B,$A4) -> 8 | U4: =COUNTIF(Restaurants!$B:$B,$A4) -> 8 | V4: tourism.rajasthan.gov.in; asi.nic.in
A5: UDR | B5: Udaipur | C5: Rajasthan | D5: North-West | E5: Heritage / Lakes / Romantic | F5: 24.5854 | G5: 73.7125 | H5: 598 | I5: Maharana Pratap (Dabok, UDR) - 22 km | J5: Udaipur City (UDZ) | K5: Sep-Mar (monsoon Aug-Sep = full lakes & green hills) | L5: Apr-Jun (hot) | M5: 3 | N5: Hindi, Mewari, English | O5: Lake Pichola, City Palace, lake-view havelis, Kumbhalgarh & Ranakpur day trips | P5: =INDEX(Budget_Tiers!$L$2:$L$46,MATCH($A5&"|Budget",Budget_Tiers!$A$2:$A$46,0)) -> 1700 | Q5: =INDEX(Budget_Tiers!$L$2:$L$46,MATCH($A5&"|Mid-range",Budget_Tiers!$A$2:$A$46,0)) -> 4650 | R5: =INDEX(Budget_Tiers!$L$2:$L$46,MATCH($A5&"|Premium",Budget_Tiers!$A$2:$A$46,0)) -> 11900 | S5: =COUNTIF(Attractions!$B:$B,$A5) -> 9 | T5: =COUNTIF(Hotels!$B:$B,$A5) -> 7 | U5: =COUNTIF(Restaurants!$B:$B,$A5) -> 6 | V5: tourism.rajasthan.gov.in; city palace museum site
A6: HMP | B6: Hampi | C6: Karnataka | D6: South | E6: Heritage / UNESCO / Backpacker | F6: 15.335 | G6: 76.46 | H6: 467 | I6: Jindal Vijaynagar (VDY, ~40 km); Hubballi (HBX, ~145 km); Bengaluru (BLR, ~340 km) | J6: Hosapete Jn / Hospet (HPT) - 13 km | K6: Oct-Feb | L6: Mar-May (very hot, 38-42C) | M6: 3 | N6: Kannada, English, Hindi, Telugu | O6: Vijayanagara ruins, boulder landscapes, Virupaksha & Vittala temples, sunrise hills, Tungabhadra coracles | P6: =INDEX(Budget_Tiers!$L$2:$L$46,MATCH($A6&"|Budget",Budget_Tiers!$A$2:$A$46,0)) -> 1200 | Q6: =INDEX(Budget_Tiers!$L$2:$L$46,MATCH($A6&"|Mid-range",Budget_Tiers!$A$2:$A$46,0)) -> 3550 | R6: =INDEX(Budget_Tiers!$L$2:$L$46,MATCH($A6&"|Premium",Budget_Tiers!$A$2:$A$46,0)) -> 8450 | S6: =COUNTIF(Attractions!$B:$B,$A6) -> 9 | T6: =COUNTIF(Hotels!$B:$B,$A6) -> 7 | U6: =COUNTIF(Restaurants!$B:$B,$A6) -> 4 | V6: karnatakatourism.org; asi.nic.in
A7: AEL | B7: Ajanta & Ellora Caves | C7: Maharashtra | D7: West | E7: Heritage / UNESCO / Caves | F7: 19.8762 | G7: 75.3433 | H7: 568 | I7: Chhatrapati Sambhajinagar (Aurangabad, IXU) - base city, 10 km | J7: Chhatrapati Sambhajinagar (AWB) | K7: Oct-Mar (Jul-Sep monsoon = lush waterfalls at Ellora) | L7: Apr-Jun (up to 42C) | M7: 3 | N7: Marathi, Hindi, English | O7: Rock-cut Buddhist murals (Ajanta), Kailasa Temple (Ellora), Daulatabad Fort, Bibi Ka Maqbara; base = Chhatrapati Sambhajinagar (formerly Aurangabad) | P7: =INDEX(Budget_Tiers!$L$2:$L$46,MATCH($A7&"|Budget",Budget_Tiers!$A$2:$A$46,0)) -> 1700 | Q7: =INDEX(Budget_Tiers!$L$2:$L$46,MATCH($A7&"|Mid-range",Budget_Tiers!$A$2:$A$46,0)) -> 4050 | R7: =INDEX(Budget_Tiers!$L$2:$L$46,MATCH($A7&"|Premium",Budget_Tiers!$A$2:$A$46,0)) -> 8550 | S7: =COUNTIF(Attractions!$B:$B,$A7) -> 7 | T7: =COUNTIF(Hotels!$B:$B,$A7) -> 6 | U7: =COUNTIF(Restaurants!$B:$B,$A7) -> 4 | V7: maharashtratourism.gov.in; asi.nic.in
A8: GOA | B8: Goa | C8: Goa | D8: West | E8: Beach / Nightlife / Heritage | F8: 15.2993 | G8: 74.124 | H8: 10 | I8: Manohar Intl, Mopa (GOX, North Goa); Dabolim (GOI, South Goa) | J8: Madgaon (MAO), Thivim (THVM), Karmali (KRMI), Vasco (VSG) | K8: Nov-Feb (peak Dec-Jan); Oct & Mar shoulder | L8: Jun-Sep (heavy monsoon, many shacks closed, sea rough) | M8: 5 | N8: Konkani, English, Hindi, Marathi | O8: Beaches, Portuguese churches & Latin quarter, seafood, flea markets, nightlife, water sports | P8: =INDEX(Budget_Tiers!$L$2:$L$46,MATCH($A8&"|Budget",Budget_Tiers!$A$2:$A$46,0)) -> 1900 | Q8: =INDEX(Budget_Tiers!$L$2:$L$46,MATCH($A8&"|Mid-range",Budget_Tiers!$A$2:$A$46,0)) -> 5450 | R8: =INDEX(Budget_Tiers!$L$2:$L$46,MATCH($A8&"|Premium",Budget_Tiers!$A$2:$A$46,0)) -> 15000 | S8: =COUNTIF(Attractions!$B:$B,$A8) -> 10 | T8: =COUNTIF(Hotels!$B:$B,$A8) -> 7 | U8: =COUNTIF(Restaurants!$B:$B,$A8) -> 7 | V8: goa-tourism.com
A9: KER | B9: Kerala Backwaters (Alleppey / Kumarakom / Kochi) | C9: Kerala | D9: South | E9: Nature / Backwaters / Wellness | F9: 9.4981 | G9: 76.3388 | H9: 1 | I9: Cochin Intl (COK) - ~85 km to Alleppey, ~90 km to Kumarakom | J9: Alappuzha (ALLP), Kottayam (KTYM), Ernakulam Jn (ERS) | K9: Oct-Mar (peak Dec-Feb) | L9: Jun-Aug (heavy rain; but good for Ayurveda) | M9: 4 | N9: Malayalam, English, Hindi | O9: Houseboats (kettuvallam), Vembanad Lake, Kuttanad paddy fields, Kumarakom birds, Fort Kochi, Ayurveda, Kerala cuisine | P9: =INDEX(Budget_Tiers!$L$2:$L$46,MATCH($A9&"|Budget",Budget_Tiers!$A$2:$A$46,0)) -> 1900 | Q9: =INDEX(Budget_Tiers!$L$2:$L$46,MATCH($A9&"|Mid-range",Budget_Tiers!$A$2:$A$46,0)) -> 4750 | R9: =INDEX(Budget_Tiers!$L$2:$L$46,MATCH($A9&"|Premium",Budget_Tiers!$A$2:$A$46,0)) -> 12000 | S9: =COUNTIF(Attractions!$B:$B,$A9) -> 8 | T9: =COUNTIF(Hotels!$B:$B,$A9) -> 7 | U9: =COUNTIF(Restaurants!$B:$B,$A9) -> 5 | V9: keralatourism.org; DTPC Alappuzha
A10: AND | B10: Andaman & Nicobar Islands | C10: Andaman & Nicobar (UT) | D10: East (Bay of Bengal) | E10: Island / Beach / Scuba | F10: 11.6234 | G10: 92.7265 | H10: 16 | I10: Veer Savarkar Intl, Port Blair (IXZ) | J10: No rail - ship/ferry from Chennai, Kolkata, Visakhapatnam | K10: Nov-Apr (peak Dec-Feb) | L10: Jun-Sep (monsoon), Oct-Nov & Apr-May cyclone spells | M10: 6 | N10: Hindi, English, Bengali, Tamil, Telugu | O10: Radhanagar & Elephant beaches, scuba/snorkelling, Cellular Jail, Ross Island, Neil Island | P10: =INDEX(Budget_Tiers!$L$2:$L$46,MATCH($A10&"|Budget",Budget_Tiers!$A$2:$A$46,0)) -> 3000 | Q10: =INDEX(Budget_Tiers!$L$2:$L$46,MATCH($A10&"|Mid-range",Budget_Tiers!$A$2:$A$46,0)) -> 6700 | R10: =INDEX(Budget_Tiers!$L$2:$L$46,MATCH($A10&"|Premium",Budget_Tiers!$A$2:$A$46,0)) -> 15700 | S10: =COUNTIF(Attractions!$B:$B,$A10) -> 9 | T10: =COUNTIF(Hotels!$B:$B,$A10) -> 7 | U10: =COUNTIF(Restaurants!$B:$B,$A10) -> 4 | V10: andaman.gov.in; A&N Tourism
A11: PON | B11: Pondicherry (Puducherry) | C11: Puducherry (UT) | D11: South | E11: Beach / French Quarter / Spiritual | F11: 11.9416 | G11: 79.8083 | H11: 3 | I11: Puducherry (PNY) - small; Chennai (MAA) ~150 km is main gateway | J11: Puducherry (PDY); Villupuram Jn (VM) ~38 km is main junction | K11: Oct-Mar | L11: Apr-Jun (hot); Oct-Dec can have heavy NE-monsoon showers | M11: 3 | N11: Tamil, French, English, Telugu, Malayalam | O11: White Town French colonial streets, cafes, Auroville, Sri Aurobindo Ashram, Promenade beach, surfing at Serenity Beach | P11: =INDEX(Budget_Tiers!$L$2:$L$46,MATCH($A11&"|Budget",Budget_Tiers!$A$2:$A$46,0)) -> 1650 | Q11: =INDEX(Budget_Tiers!$L$2:$L$46,MATCH($A11&"|Mid-range",Budget_Tiers!$A$2:$A$46,0)) -> 4550 | R11: =INDEX(Budget_Tiers!$L$2:$L$46,MATCH($A11&"|Premium",Budget_Tiers!$A$2:$A$46,0)) -> 10400 | S11: =COUNTIF(Attractions!$B:$B,$A11) -> 9 | T11: =COUNTIF(Hotels!$B:$B,$A11) -> 6 | U11: =COUNTIF(Restaurants!$B:$B,$A11) -> 7 | V11: Puducherry Tourism; auroville.org
A12: VNS | B12: Varanasi | C12: Uttar Pradesh | D12: North | E12: Spiritual / Heritage / Ghats | F12: 25.3176 | G12: 82.9739 | H12: 80 | I12: Lal Bahadur Shastri Intl (VNS) - ~26 km | J12: Varanasi Jn (BSB), Banaras (BSBS), Kashi (KEI) | K12: Oct-Mar (Nov Dev Deepawali is spectacular) | L12: Apr-Jun (45C); Jul-Sep (Ganga floods, ghats submerged) | M12: 3 | N12: Hindi, Bhojpuri, English | O12: Ganga ghats & aarti, Kashi Vishwanath, Sarnath, silk, street food, boat rides | P12: =INDEX(Budget_Tiers!$L$2:$L$46,MATCH($A12&"|Budget",Budget_Tiers!$A$2:$A$46,0)) -> 1300 | Q12: =INDEX(Budget_Tiers!$L$2:$L$46,MATCH($A12&"|Mid-range",Budget_Tiers!$A$2:$A$46,0)) -> 3500 | R12: =INDEX(Budget_Tiers!$L$2:$L$46,MATCH($A12&"|Premium",Budget_Tiers!$A$2:$A$46,0)) -> 10000 | S12: =COUNTIF(Attractions!$B:$B,$A12) -> 9 | T12: =COUNTIF(Hotels!$B:$B,$A12) -> 6 | U12: =COUNTIF(Restaurants!$B:$B,$A12) -> 5 | V12: uptourism.gov.in; Varanasi Nagar Nigam / Kashi Vishwanath Trust
A13: AMR | B13: Amritsar | C13: Punjab | D13: North | E13: Spiritual / Heritage / Food | F13: 31.634 | G13: 74.8723 | H13: 234 | I13: Sri Guru Ram Dass Jee Intl (ATQ) - ~12 km | J13: Amritsar Jn (ASR) | K13: Oct-Mar (Oct-Nov & Feb-Mar most pleasant) | L13: May-Jun (45C); Dec-Jan cold & foggy | M13: 2 | N13: Punjabi, Hindi, English | O13: Golden Temple & langar, Jallianwala Bagh, Wagah-Attari border ceremony, Amritsari kulcha & lassi | P13: =INDEX(Budget_Tiers!$L$2:$L$46,MATCH($A13&"|Budget",Budget_Tiers!$A$2:$A$46,0)) -> 1200 | Q13: =INDEX(Budget_Tiers!$L$2:$L$46,MATCH($A13&"|Mid-range",Budget_Tiers!$A$2:$A$46,0)) -> 3400 | R13: =INDEX(Budget_Tiers!$L$2:$L$46,MATCH($A13&"|Premium",Budget_Tiers!$A$2:$A$46,0)) -> 8650 | S13: =COUNTIF(Attractions!$B:$B,$A13) -> 8 | T13: =COUNTIF(Hotels!$B:$B,$A13) -> 6 | U13: =COUNTIF(Restaurants!$B:$B,$A13) -> 6 | V13: punjabtourism.gov.in; goldentempleamritsar.org (SGPC)
... A16: DAR | B16: Darjeeling | C16: West Bengal | D16: East (Himalaya) | E16: Hill Station / Tea / Toy Train | F16: 27.036 | G16: 88.2627 | H16: 2042 | I16: Bagdogra (IXB) - ~90 km | J16: New Jalpaiguri (NJP) ~88 km; Darjeeling (DJ) toy-train station | K16: Mar-May & Oct-Nov (Dec-Feb cold but clearest Kanchenjunga views) | L16: Jun-Sep (monsoon, landslides, fog) | M16: 3 | N16: Nepali, Bengali, Hindi, English | O16: Tea estates, Tiger Hill sunrise over Kanchenjunga, Darjeeling Himalayan Railway (UNESCO), monasteries, Tibetan culture | P16: =INDEX(Budget_Tiers!$L$2:$L$46,MATCH($A16&"|Budget",Budget_Tiers!$A$2:$A$46,0)) -> 1750 | Q16: =INDEX(Budget_Tiers!$L$2:$L$46,MATCH($A16&"|Mid-range",Budget_Tiers!$A$2:$A$46,0)) -> 4400 | R16: =INDEX(Budget_Tiers!$L$2:$L$46,MATCH($A16&"|Premium",Budget_Tiers!$A$2:$A$46,0)) -> 10550 | S16: =COUNTIF(Attractions!$B:$B,$A16) -> 9 | T16: =COUNTIF(Hotels!$B:$B,$A16) -> 7 | U16: =COUNTIF(Restaurants!$B:$B,$A16) -> 6 | V16: wbtourism.gov.in; IRCTC (DHR tickets)

Sheet Attractions
A1: Attraction_ID | B1: Dest_ID | C1: Destination | D1: Attraction | E1: Category | F1: Entry fee - Indians (INR) | G1: Entry fee - Foreigners (INR) | H1: Typical timings | I1: Weekly closure | J1: Time needed (hrs) | K1: Best time | L1: UNESCO | M1: Notes / tips | N1: Confidence (A/B/C)
A2: ATT-DEL-01 | B2: DEL | C2: New Delhi | D2: Red Fort (Lal Qila) | E2: Monument | F2: 35 | G2: 500 | H2: 9:30-16:30 (last entry ~16:00) | I2: Monday | J2: 2 | K2: Morning | L2: Y | M2: Mughal fort; evening sound & light show is ticketed separately; ID + bag checks at entry. | N2: B
A3: ATT-DEL-02 | B3: DEL | C3: New Delhi | D3: Humayun's Tomb | E3: Monument | F3: 35 | G3: 550 | H3: Sunrise-sunset (~6:00-18:00) | I3: None | J3: 1.5 | K3: Late afternoon (golden light) | L3: Y | M3: Precursor to the Taj Mahal; adjoining Sunder Nursery (small fee) is a good pairing. | N3: B
A4: ATT-DEL-03 | B4: DEL | C4: New Delhi | D4: Qutub Minar Complex | E4: Monument | F4: 35 | G4: 550 | H4: 7:00-17:00 | I4: None | J4: 1.5 | K4: Morning | L4: Y | M4: 73 m red-sandstone minaret, Iron Pillar, Alai Darwaza. | N4: B
A5: ATT-DEL-04 | B5: DEL | C5: New Delhi | D5: India Gate & Kartavya Path | E5: Monument / Landmark | F5: 0 | G5: 0 | H5: Open 24 hrs (best after 17:00) | I5: None | J5: 1 | K5: Evening | L5: N | M5: War memorial; Kartavya Path (formerly Rajpath) is the ceremonial boulevard to Rashtrapati Bhavan. | N5: B
A6: ATT-DEL-05 | B6: DEL | C6: New Delhi | D6: Lotus Temple (Bahai) | E6: Temple / Religious | F6: 0 | G6: 0 | H6: 9:00-17:00 (summer to ~19:00) | I6: Monday | J6: 1 | K6: Late afternoon | L6: N | M6: Silent prayer hall; no photography inside. | N6: B
A7: ATT-DEL-06 | B7: DEL | C7: New Delhi | D7: Akshardham Temple | E7: Temple / Religious | F7: 0 | G7: 0 | H7: 10:00-18:30 | I7: Monday | J7: 3-4 | K7: Afternoon-evening | L7: N | M7: Temple entry free; exhibitions & musical fountain show are separately ticketed. Phones, cameras, bags NOT allowed - lockers provided. | N7: B
A8: ATT-DEL-07 | B8: DEL | C8: New Delhi | D8: Jama Masjid | E8: Temple / Religious | F8: 0 | G8: 0 | H8: Non-prayer times (roughly 7:00-12:00, 13:30-18:30) | I8: None | J8: 1 | K8: Morning | L8: N | M8: Camera fee and minaret climb are extra (small amounts). Modest dress; cover head/legs. | N8: B
A9: ATT-DEL-08 | B9: DEL | C9: New Delhi | D9: Chandni Chowk & Old Delhi food walk | E9: Market / Food | F9: 0 | G9: 0 | H9: ~10:00-20:00 (Sunday many shops shut) | I9: Sunday (partial) | J9: 3 | K9: Late morning-evening | L9: N | M9: Paranthe Wali Gali, jalebi, kebabs, Spice Market (Khari Baoli). Use cycle-rickshaw for lanes. | N9: B
A10: ATT-DEL-09 | B10: DEL | C10: New Delhi | D10: National Museum | E10: Museum | F10: 20 | G10: 650 | H10: 10:00-18:00 | I10: Monday | J10: 2-3 | K10: Weekday morning | L10: N | M10: Harappan artefacts, miniatures, Buddhist art. | N10: C
A11: ATT-DEL-10 | B11: DEL | C11: New Delhi | D11: Jantar Mantar (Delhi) | E11: Monument | F11: 25 | G11: 200 | H11: Sunrise-sunset | I11: None | J11: 0.5 | K11: Morning | L11: N | M11: 18th-century astronomical observatory; short visit. | N11: C
A12: ATT-DEL-11 | B12: DEL | C12: New Delhi | D12: Lodhi Garden | E12: Nature / Park | F12: 0 | G12: 0 | H12: 6:00-20:00 | I12: None | J12: 1.5 | K12: Early morning | L12: N | M12: 15th-century tombs in a landscaped park; joggers' favourite. | N12: B
A13: ATT-DEL-12 | B13: DEL | C13: New Delhi | D13: Hauz Khas Village | E13: Market / Nightlife | F13: 0 | G13: 0 | H13: Cafes ~11:00-late | I13: None | J13: 2-3 | K13: Evening | L13: N | M13: Ruined madrasa & tank + cafes/boutiques. Deer park adjacent. | N13: B
... A20: ATT-AGR-07 | B20: AGR | C20: Taj Mahal (Agra) | D20: Marble inlay & leather bazaars (Sadar / Kinari) | E20: Market / Shopping | F20: 0 | G20: 0 | H20: ~10:00-20:00 | I20: Varies | J20: 2 | K20: Afternoon | L20: N | M20: Buy from govt-approved emporiums or bargain hard; commission-driven 'factory' visits common. | N20: C
A21: ATT-AGR-08 | B21: AGR | C21: Taj Mahal (Agra) | D21: Mohabbat The Taj (Kalakriti show) | E21: Activity / Show | H21: Evening shows (~18:30 & 20:30) | I21: Varies | J21: 1.5 | K21: Evening | L21: N | M21: Live dance-drama on the Taj love story at Kalakriti Cultural Centre; ticket typically ~Rs1,000-1,500 (indicative). | N21: C
A22: ATT-JAI-01 | B22: JAI | C22: Jaipur | D22: Amber (Amer) Fort | E22: Monument | F22: 100 | G22: 500 | H22: 8:00-17:30 | I22: None | J22: 3 | K22: Morning (arrive by 8:30) | L22: Y | M22: Hilltop fort-palace; Sheesh Mahal. Jeep or walking up; elephant rides run but raise welfare concerns. Evening sound & light show extra. | N22: B
A23: ATT-JAI-02 | B23: JAI | C23: Jaipur | D23: City Palace | E23: Museum / Palace | F23: 200 | G23: 700 | H23: 9:30-17:00 | I23: None | J23: 2.5 | K23: Morning | L23: N | M23: Royal residence-museum; special 'Palace' tickets cost more. | N23: B
A24: ATT-JAI-03 | B24: JAI | C24: Jaipur | D24: Hawa Mahal | E24: Monument | F24: 50 | G24: 200 | H24: 9:00-16:30 | I24: None | J24: 1 | K24: Sunrise (facade) | L24: N | M24: Facade best photographed from cafes opposite in early light. | N24: B
A25: ATT-JAI-04 | B25: JAI | C25: Jaipur | D25: Jantar Mantar | E25: Monument | F25: 50 | G25: 200 | H25: 9:00-16:30 | I25: None | J25: 1.5 | K25: Late morning | L25: Y | M25: World's largest stone sundial (Samrat Yantra). | N25: B
A26: ATT-JAI-05 | B26: JAI | C26: Jaipur | D26: Nahargarh Fort | E26: Monument / Viewpoint | F26: 50 | G26: 200 | H26: 10:00-17:30 (sunset cafes open later) | I26: None | J26: 2 | K26: Sunset | L26: N | M26: City panorama; Padao restaurant on premises. | N26: C
A27: ATT-JAI-06 | B27: JAI | C27: Jaipur | D27: Jaigarh Fort | E27: Monument | F27: 100 | G27: 200 | H27: 9:00-16:30 | I27: None | J27: 2 | K27: Afternoon | L27: N | M27: Houses Jaivana cannon; fee indicative - verify. | N27: C
A28: ATT-JAI-07 | B28: JAI | C28: Jaipur | D28: Albert Hall Museum | E28: Museum | F28: 40 | G28: 300 | H28: 9:00-17:00 (evening 19:00-22:00 also) | I28: Friday | J28: 1.5 | K28: Evening (lit up) | L28: N | M28: Indo-Saracenic building. | N28: C
A29: ATT-JAI-08 | B29: JAI | C29: Jaipur | D29: Patrika Gate | E29: Landmark | F29: 0 | G29: 0 | H29: Open 24 hrs | I29: None | J29: 0.5 | K29: Sunrise | L29: N | M29: Photo spot at Jawahar Circle. | N29: B
A30: ATT-JAI-09 | B30: JAI | C30: Jaipur | D30: Jal Mahal (view only) | E30: Landmark | F30: 0 | G30: 0 | H30: Open 24 hrs (viewing promenade) | I30: None | J30: 0.5 | K30: Sunset | L30: N | M30: Palace in Man Sagar Lake; no entry to building. | N30: B
A31: ATT-JAI-10 | B31: JAI | C31: Jaipur | D31: Johari & Bapu Bazaars | E31: Market / Shopping | F31: 0 | G31: 0 | H31: ~10:30-20:30 | I31: Sunday (partial) | J31: 3 | K31: Afternoon | L31: N | M31: Jewellery, block-print textiles, mojari shoes, lac bangles. | N31: B
A32: ATT-UDR-01 | B32: UDR | C32: Udaipur | D32: City Palace Udaipur | E32: Museum / Palace | F32: 300 | G32: 700 | H32: 9:30-17:30 | I32: None | J32: 2.5 | K32: Morning | L32: N | M32: Largest palace complex in Rajasthan on Lake Pichola; camera ticket extra. | N32: C
A33: ATT-UDR-02 | B33: UDR | C33: Udaipur | D33: Lake Pichola Boat Ride | E33: Activity / Experience | F33: 500 | G33: 700 | H33: ~10:00-18:00 | I33: Weather-dependent | J33: 1 | K33: Sunset | L33: N | M33: 30-45 min boat from City Palace jetty; Jag Mandir island stop costs more. | N33: C
... A35: ATT-UDR-04 | B35: UDR | C35: Udaipur | D35: Saheliyon Ki Bari | E35: Garden | F35: 10 | G35: 50 | H35: ~9:00-19:00 | I35: None | J35: 1 | K35: Morning | L35: N | M35: Fountain garden; fee small - verify. | N35: C
A36: ATT-UDR-05 | B36: UDR | C36: Udaipur | D36: Bagore Ki Haveli + Dharohar Folk Show | E36: Museum / Show | F36: 90 | H36: Museum ~10:00-19:00; show ~19:00 | I36: None | J36: 2 | K36: Evening | L36: N | M36: Folk dance & puppet show at Gangaur Ghat (ticket ~Rs100-150, indicative). | N36: C
A37: ATT-UDR-06 | B37: UDR | C37: Udaipur | D37: Monsoon Palace (Sajjangarh) | E37: Monument / Viewpoint | H37: ~9:30-17:30 | I37: None | J37: 1.5 | K37: Sunset | L37: N | M37: Hilltop palace; per-person + vehicle fees vary (verify at gate). | N37: C
A38: ATT-UDR-07 | B38: UDR | C38: Udaipur | D38: Vintage & Classic Car Museum | E38: Museum | H38: ~9:00-20:00 | I38: None | J38: 1 | K38: Afternoon | L38: N | M38: Maharana's car collection; ticket ~Rs350 (indicative). | N38: C
A39: ATT-UDR-08 | B39: UDR | C39: Udaipur | D39: Kumbhalgarh Fort (day trip ~85 km) | E39: Day trip / Monument | H39: ~8:00-18:00 | I39: None | J39: 3 | K39: Morning | L39: Y | M39: 2nd-longest continuous wall in the world (~36 km). Nominal entry; verify fee. | N39: C
A40: ATT-UDR-09 | B40: UDR | C40: Udaipur | D40: Ranakpur Jain Temple (day trip ~95 km) | E40: Day trip / Temple | H40: Non-Jains ~12:00-17:00 | I40: None | J40: 1.5 | K40: Afternoon | L40: N | M40: 1,444 carved marble pillars; combine with Kumbhalgarh. | N40: B
A41: ATT-HMP-01 | B41: HMP | C41: Hampi | D41: Virupaksha Temple & Hampi Bazaar | E41: Temple / Religious | F41: 0 | G41: 0 | H41: ~6:00-13:00, 15:00-20:00 | I41: None | J41: 1.5 | K41: Early morning | L41: Y | M41: Living 7th-century Shiva temple; temple elephant Lakshmi blesses morning visitors. | N41: B
A42: ATT-HMP-02 | B42: HMP | C42: Hampi | D42: Vittala Temple (Stone Chariot) | E42: Monument | F42: 40 | G42: 600 | H42: 8:30-17:30 | I42: None | J42: 2 | K42: Morning | L42: Y | M42: Musical pillars, iconic stone chariot. ASI ticket also valid for Zenana Enclosure same day (verify). | N42: B
A43: ATT-HMP-03 | B43: HMP | C43: Hampi | D43: Lotus Mahal & Elephant Stables (Zenana Enclosure) | E43: Monument | F43: 40 | G43: 600 | H43: 8:30-17:30 | I43: None | J43: 1.5 | K43: Morning | L43: Y | M43: Indo-Islamic royal quarter. | N43: B
A44: ATT-HMP-04 | B44: HMP | C44: Hampi | D44: Hemakuta Hill sunset | E44: Nature / Viewpoint | F44: 0 | G44: 0 | H44: Sunrise-sunset | I44: None | J44: 1 | K44: Sunset | L44: Y | M44: Pre-Vijayanagara shrines with Virupaksha view. | N44: B
A45: ATT-HMP-05 | B45: HMP | C45: Hampi | D45: Matanga Hill sunrise trek | E45: Nature / Trek | F45: 0 | G45: 0 | H45: Sunrise (leave ~5:15) | I45: None | J45: 1.5 | K45: Sunrise | L45: Y | M45: Short steep climb; go in a group. | N45: B
A46: ATT-HMP-06 | B46: HMP | C46: Hampi | D46: Anjaneyanadri Hill (Hanuman Temple) | E46: Temple / Trek | F46: 0 | G46: 0 | H46: ~5:30-18:00 | I46: None | J46: 2 | K46: Sunrise | L46: N | M46: ~570 steps across the river (Anegundi side). | N46: B
A47: ATT-HMP-07 | B47: HMP | C47: Hampi | D47: Achyutaraya Temple & Sule Bazaar | E47: Monument | F47: 0 | G47: 0 | H47: Sunrise-sunset | I47: None | J47: 1 | K47: Morning | L47: Y | M47: Quiet ruins beyond the main tourist circuit. | N47: B
...

Sheet Hotels
A1: Hotel_ID | B1: Dest_ID | C1: Destination | D1: Name | E1: Tier | F1: Type | G1: Area / location | H1: Price low (INR/night) | I1: Price high (INR/night) | J1: Best for | K1: Notes | L1: Confidence
A2: HOT-DEL-01 | B2: DEL | C2: New Delhi | D2: Zostel Delhi | E2: Budget | F2: Hostel | G2: Central Delhi (near metro) | H2: 700 | I2: 2500 | J2: Solo / backpackers | K2: Dorm beds + private rooms; social common area. Check current branch address. | L2: Price = C (indicative)
A3: HOT-DEL-02 | B3: DEL | C3: New Delhi | D3: Hotel Hari Piorko | E3: Budget | F3: Guesthouse | G3: Paharganj (near New Delhi station) | H3: 1500 | I3: 3200 | J3: Budget / short stays | K3: Rooftop restaurant; noisy area; good for early train. | L3: Price = C (indicative)
A4: HOT-DEL-03 | B4: DEL | C4: New Delhi | D4: Bloomrooms @ Janpath | E4: Mid-range | F4: Boutique Hotel | G4: Connaught Place / Janpath | H4: 3500 | I4: 6500 | J4: Couples / central location | K4: Design budget-boutique; walk to CP, metro. | L4: Price = C (indicative)
A5: HOT-DEL-04 | B5: DEL | C5: New Delhi | D5: Ibis New Delhi Aerocity | E5: Mid-range | F5: Hotel | G5: Aerocity (near airport) | H5: 4000 | I5: 7500 | J5: Airport transits / business | K5: Far from sights; good for late/early flights. | L5: Price = C (indicative)
A6: HOT-DEL-05 | B6: DEL | C6: New Delhi | D6: The Lalit New Delhi | E6: Premium | F6: Hotel | G6: Barakhamba Road / CP | H6: 8500 | I6: 16000 | J6: Business / families | K6: Central with metro access. | L6: Price = C (indicative)
A7: HOT-DEL-06 | B7: DEL | C7: New Delhi | D7: The Claridges | E7: Premium | F7: Heritage Hotel | G7: Aurangzeb Road (Lutyens' Delhi) | H7: 10000 | I7: 22000 | J7: Heritage feel / couples | K7: Classic 1950s luxury hotel. | L7: Price = C (indicative)
A8: HOT-DEL-07 | B8: DEL | C8: New Delhi | D8: The Imperial New Delhi | E8: Luxury | F8: Heritage Hotel | G8: Janpath | H8: 18000 | I8: 45000 | J8: Colonial luxury / special occasion | K8: 1931 Art Deco landmark; excellent garden & dining. | L8: Price = C (indicative)
A9: HOT-AGR-01 | B9: AGR | C9: Taj Mahal (Agra) | D9: Zostel Agra | E9: Budget | F9: Hostel | G9: Agra city (near Taj area) | H9: 600 | I9: 2000 | J9: Solo / backpackers | K9: Dorms & privates; check exact branch location. | L9: Price = C (indicative)
A10: HOT-AGR-02 | B10: AGR | C10: Taj Mahal (Agra) | D10: Hotel Kamal | E10: Budget | F10: Guesthouse | G10: Taj Ganj (South Gate) | H10: 1200 | I10: 3000 | J10: Budget + Taj views | K10: Walking distance to Taj; some rooms with rooftop view. | L10: Price = C (indicative)
A11: HOT-AGR-03 | B11: AGR | C11: Taj Mahal (Agra) | D11: Hotel Amar Yatri Niwas | E11: Mid-range | F11: Hotel | G11: Fatehabad Road | H11: 3000 | I11: 6000 | J11: Families / value | K11: Pool; near Taj East Gate. | L11: Price = C (indicative)
A12: HOT-AGR-04 | B12: AGR | C12: Taj Mahal (Agra) | D12: Clarks Shiraz Hotel | E12: Premium | F12: Hotel | G12: Taj Road | H12: 6500 | I12: 11000 | J12: Families / groups | K12: Well-known 5-star; rooftop restaurant. | L12: Price = C (indicative)
A13: HOT-AGR-05 | B13: AGR | C13: Taj Mahal (Agra) | D13: Trident Agra | E13: Premium | F13: Hotel | G13: Taj East Gate Road | H13: 6500 | I13: 13000 | J13: Families / couples | K13: Garden property near Taj. | L13: Price = C (indicative)
... A102: HOT-DAR-07 | B102: DAR | C102: Darjeeling | D102: Glenburn Tea Estate | E102: Luxury | F102: Tea Estate Bungalow | G102: Near Darjeeling (Glenburn) | H102: 25000 | I102: 60000 | J102: Luxury / tea lovers | K102: Full-board plantation stay. | L102: Price = C (indicative)

Sheet Restaurants
A1: Restaurant_ID | B1: Dest_ID | C1: Destination | D1: Name | E1: Cuisine | F1: Type | G1: Area | H1: Price for two - low (INR) | I1: Price for two - high (INR) | J1: Veg / Non-veg | K1: Must try | L1: Notes | M1: Confidence
A2: RES-DEL-01 | B2: DEL | C2: New Delhi | D2: Karim's | E2: Mughlai / Non-veg | F2: Iconic eatery | G2: Jama Masjid, Old Delhi | H2: 600 | I2: 1000 | J2: Mostly non-veg | K2: Mutton burra, korma, nihari | L2: Since 1913; multiple branches. | M2: Price = C (indicative)
A3: RES-DEL-02 | B3: DEL | C3: New Delhi | D3: Paranthe Wali Gali | E3: North Indian / Street | F3: Street stalls | G3: Chandni Chowk | H3: 150 | I3: 400 | J3: Veg | K3: Stuffed parathas | L3: Lane of parantha shops. | M3: Price = C (indicative)
A4: RES-DEL-03 | B4: DEL | C4: New Delhi | D4: Old Famous Jalebi Wala | E4: Street sweets | F4: Sweet shop | G4: Dariba Kalan, Chandni Chowk | H4: 80 | I4: 200 | J4: Veg | K4: Hot jalebi | L4: Iconic. | M4: Price = C (indicative)
A5: RES-DEL-04 | B5: DEL | C5: New Delhi | D5: Saravana Bhavan | E5: South Indian | F5: Restaurant chain | G5: Connaught Place | H5: 600 | I5: 1000 | J5: Veg | K5: Dosa, thali | L5: Reliable veg chain. | M5: Price = C (indicative)
A6: RES-DEL-05 | B6: DEL | C6: New Delhi | D6: Andhra Bhawan Canteen | E6: Andhra | F6: Canteen | G6: Ashoka Road | H6: 300 | I6: 500 | J6: Veg & Non-veg | K6: Andhra meals | L6: Very cheap, packed at lunch. | M6: Price = C (indicative)
A7: RES-DEL-06 | B7: DEL | C7: New Delhi | D7: Bukhara (ITC Maurya) | E7: North-West Frontier | F7: Fine dining | G7: Chanakyapuri | H7: 9000 | I7: 14000 | J7: Non-veg heavy | K7: Dal Bukhara, sikandari raan | L7: Reservation needed; dress smart. | M7: Price = C (indicative)
A8: RES-DEL-07 | B8: DEL | C8: New Delhi | D8: Indian Accent | E8: Modern Indian | F8: Fine dining | G8: Lodhi Road (The Lodhi) | H8: 15000 | I8: 22000 | J8: Veg & Non-veg | K8: Chef tasting menu | L8: Reservation needed. | M8: Price = C (indicative)
A9: RES-AGR-01 | B9: AGR | C9: Taj Mahal (Agra) | D9: Joney's Place | E9: Indian / Backpacker | F9: Cafe | G9: Taj Ganj | H9: 300 | I9: 600 | J9: Veg-focused | K9: Banana lassi, thali | L9: Backpacker favourite near Taj. | M9: Price = C (indicative)
A10: RES-AGR-02 | B10: AGR | C10: Taj Mahal (Agra) | D10: Pinch of Spice | E10: North Indian | F10: Restaurant | G10: Fatehabad Road | H10: 1000 | I10: 1800 | J10: Veg & Non-veg | K10: Butter chicken, dal | L10: Popular with tour groups. | M10: Price = C (indicative)
A11: RES-AGR-03 | B11: AGR | C11: Taj Mahal (Agra) | D11: Panchhi Petha | E11: Sweets | F11: Sweet shop | G11: Multiple in Agra | H11: 100 | I11: 400 | J11: Veg | K11: Petha (many flavours) | L11: Agra's signature sweet. | M11: Price = C (indicative)
A12: RES-AGR-04 | B12: AGR | C12: Taj Mahal (Agra) | D12: Sheroes Hangout | E12: Cafe | F12: Community cafe | G12: Fatehabad Road | H12: 300 | I12: 700 | J12: Veg & Non-veg | K12: Coffee & snacks | L12: Cafe run by acid-attack survivors; pay-what-you-like model in some sections. | M12: Price = C (indicative)
A13: RES-AGR-05 | B13: AGR | C13: Taj Mahal (Agra) | D13: Peshawri (ITC Mughal) | E13: North-West Frontier | F13: Fine dining | G13: Taj East Gate Road | H13: 6000 | I13: 9000 | J13: Non-veg heavy | K13: Sikandari raan, dal | L13: Reservation recommended. | M13: Price = C (indicative)
... A85: RES-DAR-06 | B85: DAR | C85: Darjeeling | D85: Frank Ross | E85: Continental | F85: Restaurant | G85: Darjeeling | H85: 700 | I85: 1500 | J85: Veg & Non-veg | K85: Steak, pizza | L85: Old favourite. | M85: Price = C (indicative)

Sheet Transport
A1: Dest_ID | B1: Destination | C1: Category | D1: Mode | E1: Route / service | F1: Typical duration | G1: Cost low (INR) | H1: Cost high (INR) | I1: Unit | J1: Notes
A2: DEL | B2: New Delhi | C2: Getting there | D2: Flight | E2: Any metro city -> DEL (IGI Airport) | F2: 1.5-3 h from major metros | G2: 3000 | H2: 9000 | I2: per person one-way | J2: Book 3-4 weeks ahead for lowest fares.
A3: DEL | B3: New Delhi | C3: Getting there | D3: Train | E3: Major metros -> New Delhi / Old Delhi / H. Nizamuddin | F3: Rajdhani ~16-17 h from Mumbai/Kolkata | G3: 1800 | H3: 4500 | I3: per person (3AC-2AC) | J3: Use IRCTC; Tatkal opens 1 day earlier.
A4: DEL | B4: New Delhi | C4: Local | D4: Metro | E4: Delhi Metro (Airport Express to New Delhi) | F4: 20 min | G4: 10 | H4: 60 | I4: per ride | J4: Most efficient; Airport Express ~Rs60 to New Delhi.
A5: DEL | B5: New Delhi | C5: Local | D5: App cab / auto | E5: Ola / Uber / Rapido | F5: varies | G5: 100 | H5: 600 | I5: per short-to-medium ride | J5: Autos are metered in principle; app cabs ~Rs12-18/km.
A6: DEL | B6: New Delhi | C6: Local | D6: Cycle-rickshaw / e-rickshaw | E6: Old Delhi lanes | F6: 10-30 min | G6: 30 | H6: 150 | I6: per ride | J6: Agree price first.
A7: DEL | B7: New Delhi | C7: Local | D7: Hop-on Hop-off / sightseeing cab | E7: Full-day city tour by cab | F7: 8 h | G7: 1800 | H7: 3500 | I7: per vehicle | J7: Typically 8 h / 80 km.
A8: AGR | B8: Taj Mahal (Agra) | C8: Getting there | D8: Train | E8: Delhi (H. Nizamuddin) -> Agra Cantt (Gatimaan Express / Shatabdi / Vande Bharat variants) | F8: ~1 h 40 min - 2 h | G8: 700 | H8: 1700 | I8: per person (CC/EC) | J8: Fastest option; Gatimaan Express does not run Fridays (verify current schedule).
A9: AGR | B9: Taj Mahal (Agra) | C9: Getting there | D9: Road | E9: Delhi -> Agra via Yamuna Expressway | F9: 3.5-4.5 h | G9: 4000 | H9: 6500 | I9: per vehicle | J9: One-way private cab; tolls included in most quotes.
A10: AGR | B10: Taj Mahal (Agra) | C10: Getting there | D10: Bus | E10: Delhi -> Agra (UPSRTC / private AC) | F10: 4.5-6 h | G10: 300 | H10: 900 | I10: per person
A11: AGR | B11: Taj Mahal (Agra) | C11: Local | D11: E-rickshaw / tonga | E11: Taj Ganj / Taj East Gate | F11: short | G11: 30 | H11: 150 | I11: per ride | J11: Petrol vehicles restricted near Taj; use electric/rickshaw.
A12: AGR | B12: Taj Mahal (Agra) | C12: Local | D12: App cab | E12: Ola / Uber | F12: varies | G12: 100 | H12: 500 | I12: per ride
A13: AGR | B13: Taj Mahal (Agra) | C13: Local | D13: Full-day sightseeing cab | E13: Taj + Agra Fort + Fatehpur Sikri | F13: 8-10 h | G13: 2500 | H13: 4500 | I13: per vehicle
A14: JAI | B14: Jaipur | C14: Getting there | D14: Train | E14: Delhi -> Jaipur (Vande Bharat / Shatabdi / Ajmer Shatabdi) | F14: ~4.5 h | G14: 700 | H14: 1900 | I14: per person (CC/EC)
A15: JAI | B15: Jaipur | C15: Getting there | D15: Road | E15: Delhi -> Jaipur via NH48 | F15: 5-6 h | G15: 4500 | H15: 6500 | I15: per vehicle
A16: JAI | B16: Jaipur | C16: Getting there | D16: Bus | E16: Delhi -> Jaipur (RSRTC Volvo) | F16: 5-6 h | G16: 500 | H16: 900 | I16: per person
A17: JAI | B17: Jaipur | C17: Local | D17: Metro | E17: Jaipur Metro (Mansarovar-Badi Chaupar) | F17: ~15-20 min | G17: 10 | H17: 30 | I17: per ride | J17: Reaches Old City edge.
A18: JAI | B18: Jaipur | C18: Local | D18: Auto-rickshaw | E18: City rides | F18: 15-30 min | G18: 100 | H18: 300 | I18: per ride | J18: Negotiate or use app.
A19: JAI | B19: Jaipur | C19: Local | D19: Full-day sightseeing cab | E19: Amber + City Palace + Hawa Mahal + Nahargarh | F19: 8 h | G19: 1800 | H19: 3200 | I19: per vehicle | J19: 8 h / 80 km typical.
A20: UDR | B20: Udaipur | C20: Getting there | D20: Flight | E20: Delhi/Mumbai/Bengaluru -> Udaipur (UDR) | F20: 1.5-2.5 h | G20: 3500 | H20: 8000 | I20: per person one-way
A21: UDR | B21: Udaipur | C21: Getting there | D21: Train | E21: Delhi/Jaipur/Ahmedabad -> Udaipur City | F21: overnight 10-12 h from Delhi | G21: 600 | H21: 2200 | I21: per person
A22: UDR | B22: Udaipur | C22: Getting there | D22: Bus | E22: Jaipur -> Udaipur (RSRTC/private) | F22: 7-9 h | G22: 600 | H22: 1500 | I22: per person
A23: UDR | B23: Udaipur | C23: Local | D23: Auto-rickshaw | E23: Old city to Fateh Sagar | F23: 10-20 min | G23: 80 | H23: 250 | I23: per ride
A24: UDR | B24: Udaipur | C24: Local | D24: Scooter rental | E24: Day rental | F24: - | G24: 400 | H24: 700 | I24: per day
A25: UDR | B25: Udaipur | C25: Local | D25: Day-trip cab | E25: Kumbhalgarh + Ranakpur (~180 km) | F25: 8-10 h | G25: 3500 | H25: 5500 | I25: per vehicle
A26: HMP | B26: Hampi | C26: Getting there | D26: Train | E26: Bengaluru -> Hosapete (Hampi Express / other overnight trains) | F26: ~8-11 h | G26: 300 | H26: 1500 | I26: per person
A27: HMP | B27: Hampi | C27: Getting there | D27: Bus | E27: Bengaluru -> Hospet (KSRTC / private sleeper) | F27: 8-9 h | G27: 700 | H27: 1800 | I27: per person | J27: Common overnight option.
A28: HMP | B28: Hampi | C28: Getting there | D28: Flight | E28: Jindal Vijaynagar (VDY) / Hubballi (HBX) | F28: varies | G28: 3500 | H28: 8000 | I28: per person | J28: Limited routes; check current schedule.
A29: HMP | B29: Hampi | C29: Local | D29: Bus / auto | E29: Hospet -> Hampi (13 km) | F29: 20-30 min | G29: 20 | H29: 500 | I29: per person (bus) / per auto
A30: HMP | B30: Hampi | C30: Local | D30: Bicycle rental | E30: Day | F30: - | G30: 100 | H30: 200 | I30: per day | J30: Great way to explore ruins.
A31: HMP | B31: Hampi | C31: Local | D31: Scooter / EV rental | E31: Day | F31: - | G31: 300 | H31: 600 | I31: per day
A32: HMP | B32: Hampi | C32: Local | D32: Auto day-tour | E32: Main sites | F32: 6-8 h | G32: 1000 | H32: 1800 | I32: per vehicle
A33: AEL | B33: Ajanta & Ellora Caves | C33: Getting there | D33: Flight | E33: Mumbai/Delhi/Hyderabad/Bengaluru -> Chhatrapati Sambhajinagar (IXU) | F33: 1-2 h | G33: 3500 | H33: 9000 | I33: per person one-way
A34: AEL | B34: Ajanta & Ellora Caves | C34: Getting there | D34: Train | E34: Mumbai -> Chhatrapati Sambhajinagar (Devgiri Exp / Jan Shatabdi) | F34: ~6-7 h | G34: 400 | H34: 1500 | I34: per person
A35: AEL | B35: Ajanta & Ellora Caves | C35: Local | D35: Taxi | E35: Aurangabad -> Ellora (30 km) round trip | F35: ~1 h each way | G35: 800 | H35: 1500 | I35: per vehicle | J35: Add Daulatabad / Grishneshwar.
A36: AEL | B36: Ajanta & Ellora Caves | C36: Local | D36: Taxi | E36: Aurangabad -> Ajanta (~105 km) round trip | F36: 2.5-3 h each way | G36: 2500 | H36: 4500 | I36: per vehicle | J36: Full-day; closed Monday.
A37: AEL | B37: Ajanta & Ellora Caves | C37: Local | D37: MSRTC bus | E37: Aurangabad -> Ellora | F37: ~1-1.5 h | G37: 30 | H37: 80 | I37: per person
A38: AEL | B38: Ajanta & Ellora Caves | C38: Local | D38: MTDC / shuttle bus | E38: Ajanta T-junction -> caves | F38: ~15 min | G38: 20 | H38: 60 | I38: per person | J38: Private vehicles stop at T-junction.
A39: GOA | B39: Goa | C39: Getting there | D39: Flight | E39: Delhi/Mumbai/Bengaluru -> Goa (GOX Mopa or GOI Dabolim) | F39: 1.5-2.5 h | G39: 3000 | H39: 9000 | I39: per person one-way | J39: Mopa serves North Goa.
A40: GOA | B40: Goa | C40: Getting there | D40: Train | E40: Mumbai -> Madgaon (Vande Bharat / Konkan Rly) | F40: ~8-12 h | G40: 800 | H40: 2700 | I40: per person | J40: Konkan Railway scenic route.
...

Sheet Seasons
A1: Dest_ID | B1: Destination | C1: Season | D1: Months | E1: Typical temp (C) | F1: Rainfall | G1: Crowds / prices | H1: Notes
A2: DEL | B2: New Delhi | C2: Winter | D2: Dec-Feb | E2: 5-20 | F2: Low | G2: Peak; fog | H2: Foggy mornings; pollution can be severe Nov-Jan.
A3: DEL | B3: New Delhi | C3: Summer | D3: Apr-Jun | E3: 25-45 | F3: Very low | G3: Low; hot | H3: Heat waves; stay indoors midday.
A4: DEL | B4: New Delhi | C4: Monsoon | D4: Jul-Sep | E4: 26-36 | F4: High | G4: Off-peak | H4: Humid; occasional flooding.
A5: DEL | B5: New Delhi | C5: Autumn/Spring | D5: Oct-Nov, Mar | E5: 15-32 | F5: Low | G5: Good | H5: Best sightseeing weather.
A6: AGR | B6: Taj Mahal (Agra) | C6: Winter | D6: Dec-Feb | E6: 5-20 | F6: Low | G6: Peak; fog | H6: Morning fog can hide the Taj; Taj Mahotsav in Feb.
A7: AGR | B7: Taj Mahal (Agra) | C7: Summer | D7: Apr-Jun | E7: 25-45 | F7: Very low | G7: Low | H7: Brutal heat.
A8: AGR | B8: Taj Mahal (Agra) | C8: Monsoon | D8: Jul-Sep | E8: 26-35 | F8: High | G8: Low | H8: Humid; lush gardens.
A9: AGR | B9: Taj Mahal (Agra) | C9: Autumn/Spring | D9: Oct-Nov, Mar | E9: 15-32 | F9: Low | G9: Good | H9: Comfortable.
A10: JAI | B10: Jaipur | C10: Winter | D10: Dec-Feb | E10: 8-23 | F10: Low | G10: Peak | H10: Cool days; JLF late Jan.
A11: JAI | B11: Jaipur | C11: Summer | D11: Apr-Jun | E11: 27-45 | F11: Very low | G11: Low | H11: Hot.
A12: JAI | B12: Jaipur | C12: Monsoon | D12: Jul-Sep | E12: 25-34 | F12: Moderate | G12: Off-peak | H12: Green Aravallis; forts less crowded.
... A61: DAR | B61: Darjeeling | C61: Winter | D61: Dec-Feb | E61: 2-10 | F61: Low | G61: Moderate | H61: Cold; snow possible; crisp views.

Sheet Month_Grid
A1: Dest_ID | B1: Destination | C1: Jan | D1: Feb | E1: Mar | F1: Apr | G1: May | H1: Jun | I1: Jul | J1: Aug | K1: Sep | L1: Oct | M1: Nov | N1: Dec
A2: DEL | B2: New Delhi | C2: 3 | D2: 4 | E2: 5 | F2: 3 | G2: 1 | H2: 1 | I2: 2 | J2: 2 | K2: 3 | L2: 4 | M2: 3 | N2: 3
A3: AGR | B3: Taj Mahal (Agra) | C3: 3 | D3: 4 | E3: 5 | F3: 3 | G3: 1 | H3: 1 | I3: 2 | J3: 2 | K3: 3 | L3: 4 | M3: 4 | N3: 3
A4: JAI | B4: Jaipur | C4: 4 | D4: 5 | E4: 4 | F4: 2 | G4: 1 | H4: 1 | I4: 2 | J4: 3 | K4: 3 | L4: 5 | M4: 5 | N4: 5
A5: UDR | B5: Udaipur | C5: 4 | D5: 5 | E5: 4 | F5: 2 | G5: 1 | H5: 1 | I5: 3 | J5: 4 | K5: 4 | L5: 5 | M5: 5 | N5: 5
A6: HMP | B6: Hampi | C6: 5 | D6: 5 | E6: 3 | F6: 2 | G6: 1 | H6: 3 | I6: 3 | J6: 3 | K6: 3 | L6: 4 | M6: 5 | N6: 5
A7: AEL | B7: Ajanta & Ellora Caves | C7: 4 | D7: 4 | E7: 3 | F7: 2 | G7: 1 | H7: 2 | I7: 4 | J7: 4 | K7: 4 | L7: 4 | M7: 5 | N7: 5
A8: GOA | B8: Goa | C8: 5 | D8: 5 | E8: 4 | F8: 3 | G8: 2 | H8: 1 | I8: 1 | J8: 1 | K8: 2 | L8: 3 | M8: 5 | N8: 5
A9: KER | B9: Kerala Backwaters (Alleppey / Kumarakom / Kochi) | C9: 5 | D9: 5 | E9: 4 | F9: 3 | G9: 2 | H9: 2 | I9: 2 | J9: 2 | K9: 3 | L9: 3 | M9: 4 | N9: 5
A10: AND | B10: Andaman & Nicobar Islands | C10: 5 | D10: 5 | E10: 5 | F10: 4 | G10: 3 | H10: 1 | I10: 1 | J10: 1 | K10: 2 | L10: 3 | M10: 4 | N10: 5
A11: PON | B11: Pondicherry (Puducherry) | C11: 5 | D11: 5 | E11: 4 | F11: 2 | G11: 1 | H11: 2 | I11: 2 | J11: 3 | K11: 3 | L11: 3 | M11: 3 | N11: 4
A12: VNS | B12: Varanasi | C12: 3 | D12: 4 | E12: 5 | F12: 2 | G12: 1 | H12: 1 | I12: 1 | J12: 1 | K12: 3 | L12: 4 | M12: 5 | N12: 4
A13: AMR | B13: Amritsar | C13: 3 | D13: 4 | E13: 5 | F13: 3 | G13: 1 | H13: 1 | I13: 2 | J13: 2 | K13: 3 | L13: 5 | M13: 5 | N13: 3
... A16: DAR | B16: Darjeeling | C16: 3 | D16: 3 | E16: 5 | F16: 5 | G16: 4 | H16: 2 | I16: 1 | J16: 1 | K16: 2 | L16: 5 | M16: 5 | N16: 4
A18: Scale: 1 = avoid (extreme heat/rain/closures), 3 = OK, 5 = ideal. Judgement-based summary of climate & access patterns.

Sheet Budget_Tiers
A1: Key | B1: Dest_ID | C1: Destination | D1: Tier | E1: Stay per room/night (INR) | F1: Food per person/day (INR) | G1: Local transport per person/day (INR) | H1: Activities & entry fees per person/day (INR) | I1: Misc per person/day (INR) | J1: Fixed extras per person per trip (INR) | K1: Extras note | L1: Total per person/day (INR, 2 sharing a room)
A2: =B2&"|"&D2 -> DEL|Budget | B2: DEL | C2: New Delhi | D2: Budget | E2: 1500 | F2: 500 | G2: 250 | H2: 150 | I2: 100 | J2: 0 | K2: No fixed extras | L2: =E2/2+F2+G2+H2+I2 -> 1750
A3: =B3&"|"&D3 -> DEL|Mid-range | B3: DEL | C3: New Delhi | D3: Mid-range | E3: 4500 | F3: 1200 | G3: 500 | H3: 350 | I3: 200 | J3: 0 | K3: No fixed extras | L3: =E3/2+F3+G3+H3+I3 -> 4500
A4: =B4&"|"&D4 -> DEL|Premium | B4: DEL | C4: New Delhi | D4: Premium | E4: 12000 | F4: 3000 | G4: 1200 | H4: 800 | I4: 500 | J4: 0 | K4: No fixed extras | L4: =E4/2+F4+G4+H4+I4 -> 11500
A5: =B5&"|"&D5 -> AGR|Budget | B5: AGR | C5: Taj Mahal (Agra) | D5: Budget | E5: 1200 | F5: 450 | G5: 250 | H5: 350 | I5: 100 | J5: 0 | K5: Taj + Fort entry inside activities | L5: =E5/2+F5+G5+H5+I5 -> 1750
A6: =B6&"|"&D6 -> AGR|Mid-range | B6: AGR | C6: Taj Mahal (Agra) | D6: Mid-range | E6: 4000 | F6: 1200 | G6: 600 | H6: 500 | I6: 200 | J6: 0 | K6: Includes guide & Fatehpur Sikri | L6: =E6/2+F6+G6+H6+I6 -> 4500
A7: =B7&"|"&D7 -> AGR|Premium | B7: AGR | C7: Taj Mahal (Agra) | D7: Premium | E7: 10000 | F7: 2800 | G7: 1500 | H7: 900 | I7: 500 | J7: 0 | K7: Private car/guide | L7: =E7/2+F7+G7+H7+I7 -> 10700
A8: =B8&"|"&D8 -> JAI|Budget | B8: JAI | C8: Jaipur | D8: Budget | E8: 1200 | F8: 450 | G8: 250 | H8: 300 | I8: 100 | J8: 0 | K8: Monument combo ticket / cheap entries | L8: =E8/2+F8+G8+H8+I8 -> 1700
A9: =B9&"|"&D9 -> JAI|Mid-range | B9: JAI | C9: Jaipur | D9: Mid-range | E9: 3800 | F9: 1100 | G9: 550 | H9: 450 | I9: 200 | J9: 0 | K9: No fixed extras | L9: =E9/2+F9+G9+H9+I9 -> 4200
A10: =B10&"|"&D10 -> JAI|Premium | B10: JAI | C10: Jaipur | D10: Premium | E10: 10000 | F10: 2800 | G10: 1300 | H10: 800 | I10: 500 | J10: 0 | K10: No fixed extras | L10: =E10/2+F10+G10+H10+I10 -> 10400
A11: =B11&"|"&D11 -> UDR|Budget | B11: UDR | C11: Udaipur | D11: Budget | E11: 1200 | F11: 450 | G11: 250 | H11: 300 | I11: 100 | J11: 0 | K11: No fixed extras | L11: =E11/2+F11+G11+H11+I11 -> 1700
A12: =B12&"|"&D12 -> UDR|Mid-range | B12: UDR | C12: Udaipur | D12: Mid-range | E12: 4500 | F12: 1200 | G12: 500 | H12: 500 | I12: 200 | J12: 0 | K12: No fixed extras | L12: =E12/2+F12+G12+H12+I12 -> 4650
A13: =B13&"|"&D13 -> UDR|Premium | B13: UDR | C13: Udaipur | D13: Premium | E13: 12000 | F13: 3000 | G13: 1400 | H13: 900 | I13: 600 | J13: 0 | K13: No fixed extras | L13: =E13/2+F13+G13+H13+I13 -> 11900
... A46: =B46&"|"&D46 -> DAR|Premium | B46: DAR | C46: Darjeeling | D46: Premium | E46: 9500 | F46: 2800 | G46: 1600 | H46: 900 | I46: 500 | J46: 0 | K46: No fixed extras | L46: =E46/2+F46+G46+H46+I46 -> 10550
A48: Legend / assumptions
A49: Blue cells are editable inputs (indicative INR, 2025-26 price levels). Black cells are formulas.
A50: Stay cost is per ROOM per night (double occupancy); Total per person/day = stay/2 + food + local transport + activities + misc.
A51: Tier 'Budget' ~ hostels/guesthouses + street food + public transport; 'Mid-range' ~ 3-star/heritage hotels + restaurants + cabs; 'Premium' ~ 4-5 star + private car/guide.
A52: Fixed extras: Kerala houseboat share, Andaman ferries, Ladakh environment fee etc. Airfare to/from the destination is NOT included.
A53: Assumptions are estimates derived from the Hotels / Restaurants / Transport sheets; adjust as you verify live prices.

Sheet Budget_Estimator
A1: Budget Estimator (indicative, INR)
A2: Change the yellow cells. Estimates exclude airfare to/from the destination. Based on Budget_Tiers inputs (edit there).
A4: Destination | B4: Goa
A5: Budget tier | B5: Mid-range
A6: Trip length (days) | B6: 5
A7: Travellers | B7: 2
A8: Contingency % | B8: 0.1
A10: Destination ID | B10: =INDEX(Destinations!$A$2:$A$16,MATCH(B4,Destinations!$B$2:$B$16,0)) -> GOA
A11: Nights | B11: =MAX(B6-1,0) -> 4
A12: Rooms needed (2 per room) | B12: =ROUNDUP(B7/2,0) -> 1
A13: Tier row (lookup) | B13: =MATCH(B10&"|"&B5,Budget_Tiers!$A$2:$A$46,0) -> 20
A15: COST BREAKDOWN (INR)
A16: Stay | B16: =B11*B12*INDEX(Budget_Tiers!$E$2:$E$46,B13) -> 18000
A17: Food | B17: =B6*B7*INDEX(Budget_Tiers!$F$2:$F$46,B13) -> 15000
A18: Local transport | B18: =B6*B7*INDEX(Budget_Tiers!$G$2:$G$46,B13) -> 7000
A19: Activities & entry fees | B19: =B6*B7*INDEX(Budget_Tiers!$H$2:$H$46,B13) -> 7000
A20: Miscellaneous | B20: =B6*B7*INDEX(Budget_Tiers!$I$2:$I$46,B13) -> 3000
A21: Fixed extras (ferries, houseboat, permits) | B21: =B7*INDEX(Budget_Tiers!$J$2:$J$46,B13) -> 0
A22: Subtotal | B22: =SUM(B16:B21) -> 50000
A23: Contingency | B23: =B22*B8 -> 5000
A24: GRAND TOTAL (all travellers) | B24: =B22+B23 -> 55000
A25: Per person | B25: =B24/B7 -> 27500
A26: Per person per day | B26: =B25/B6 -> 5500
A27: Extras note | B27: =INDEX(Budget_Tiers!$K$2:$K$46,B13) -> No fixed extras
A30: COMPARE ALL TIERS FOR THIS DESTINATION (same days & travellers)
A31: Tier | B31: Row | C31: Stay | D31: Food | E31: Local transport | F31: Activities | G31: Misc | H31: Fixed extras | I31: Total incl. contingency | J31: Per person
A32: Budget | B32: =MATCH($B$10&"|"&A32,Budget_Tiers!$A$2:$A$46,0) -> 19 | C32: =$B$11*$B$12*INDEX(Budget_Tiers!$E$2:$E$46,B32) -> 4000 | D32: =$B$6*$B$7*INDEX(Budget_Tiers!$F$2:$F$46,B32) -> 6000 | E32: =$B$6*$B$7*INDEX(Budget_Tiers!$G$2:$G$46,B32) -> 3500 | F32: =$B$6*$B$7*INDEX(Budget_Tiers!$H$2:$H$46,B32) -> 3000 | G32: =$B$6*$B$7*INDEX(Budget_Tiers!$I$2:$I$46,B32) -> 1500 | H32: =$B$7*INDEX(Budget_Tiers!$J$2:$J$46,B32) -> 0 | I32: =SUM(C32:H32)*(1+$B$8) -> 19800 | J32: =I32/$B$7 -> 9900
A33: Mid-range | B33: =MATCH($B$10&"|"&A33,Budget_Tiers!$A$2:$A$46,0) -> 20 | C33: =$B$11*$B$12*INDEX(Budget_Tiers!$E$2:$E$46,B33) -> 18000 | D33: =$B$6*$B$7*INDEX(Budget_Tiers!$F$2:$F$46,B33) -> 15000 | E33: =$B$6*$B$7*INDEX(Budget_Tiers!$G$2:$G$46,B33) -> 7000 | F33: =$B$6*$B$7*INDEX(Budget_Tiers!$H$2:$H$46,B33) -> 7000 | G33: =$B$6*$B$7*INDEX(Budget_Tiers!$I$2:$I$46,B33) -> 3000 | H33: =$B$7*INDEX(Budget_Tiers!$J$2:$J$46,B33) -> 0 | I33: =SUM(C33:H33)*(1+$B$8) -> 55000 | J33: =I33/$B$7 -> 27500
A34: Premium | B34: =MATCH($B$10&"|"&A34,Budget_Tiers!$A$2:$A$46,0) -> 21 | C34: =$B$11*$B$12*INDEX(Budget_Tiers!$E$2:$E$46,B34) -> 60000 | D34: =$B$6*$B$7*INDEX(Budget_Tiers!$F$2:$F$46,B34) -> 35000 | E34: =$B$6*$B$7*INDEX(Budget_Tiers!$G$2:$G$46,B34) -> 18000 | F34: =$B$6*$B$7*INDEX(Budget_Tiers!$H$2:$H$46,B34) -> 15000 | G34: =$B$6*$B$7*INDEX(Budget_Tiers!$I$2:$I$46,B34) -> 7000 | H34: =$B$7*INDEX(Budget_Tiers!$J$2:$J$46,B34) -> 0 | I34: =SUM(C34:H34)*(1+$B$8) -> 148500 | J34: =I34/$B$7 -> 74250
A36: Notes: (1) Prices are indicative and change by season. (2) Luxury stays are listed in the Hotels sheet; add their nightly price manually to estimate. (3) Airfare/train fare to the destination is excluded.

Sheet Festivals
A1: Dest_ID | B1: Destination | C1: Festival / event | D1: Typical timing | E1: Notes
A2: DEL | B2: New Delhi | C2: Republic Day Parade | D2: 26 Jan | E2: Kartavya Path; tickets in advance.
A3: DEL | B3: New Delhi | C3: Diwali | D3: Oct/Nov | E3: Very crowded; heavy air pollution.
A4: AGR | B4: Taj Mahal (Agra) | C4: Taj Mahotsav | D4: Feb (10 days) | E4: Craft & culture fair at Shilpgram.
A5: JAI | B5: Jaipur | C5: Jaipur Literature Festival | D5: Late Jan | E5: Diggi Palace; book early.
A6: JAI | B6: Jaipur | C6: Teej / Gangaur | D6: Jul-Aug / Mar-Apr | E6: Processions of Rajasthani culture.
A7: UDR | B7: Udaipur | C7: Mewar Festival | D7: Mar-Apr | E7: Spring festival with lakeside events.
A8: HMP | B8: Hampi | C8: Hampi Utsav | D8: Nov (varies by year) | E8: Cultural festival; check state announcements.
A9: AEL | B9: Ajanta & Ellora Caves | C9: Ellora-Ajanta Festival | D9: Nov-Dec (irregular) | E9: Held by MTDC in some years; verify.
A10: GOA | B10: Goa | C10: Carnival | D10: Feb/Mar | E10: Parades in Panaji & Margao.
A11: GOA | B11: Goa | C11: Feast of St Francis Xavier | D11: 3 Dec | E11: Old Goa; large pilgrim crowds.
A12: GOA | B12: Goa | C12: Christmas & New Year | D12: 25 Dec-1 Jan | E12: Peak crowds and prices.
... A26: DAR | B26: Darjeeling | C26: Tea & Tourism Festival | D26: Nov | E26: Tea tasting events.

Sheet Practical_Info
A1: Dest_ID | B1: Destination | C1: Emergency | D1: Health & safety | E1: Connectivity & cash | F1: Dress / culture | G1: Permits & fees | H1: Common cautions
A2: DEL | B2: New Delhi | C2: 112 (police/fire/ambulance); Tourist helpline 1363 | D2: Drink bottled/filtered water; air pollution Nov-Jan (use N95). | E2: Excellent 4G/5G; ATMs everywhere; UPI widely accepted. | F2: Modest dress at mosques/gurudwaras. | G2: None for domestic tourists; foreigners need valid visa / e-visa. | H2: Common tout scams near stations & Connaught Place; use app cabs / prepaid taxis.
A3: AGR | B3: Taj Mahal (Agra) | C3: 112; Tourist helpline 1363 | D3: Heat & dehydration Apr-Jun. | E3: Good 4G; ATMs near Taj East Gate. | F3: Modest dress at Taj mosque; shoe covers at mausoleum. | G3: Taj closed Friday; buy tickets at gates or online; foreigners also pay ADA fees. | H3: Touts, fake 'guides', commission shopping; agree price first.
A4: JAI | B4: Jaipur | C4: 112; 1363 | D4: Heat; drink safe water. | E4: Good 4G; UPI widely accepted. | F4: Modest dress at temples. | G4: ASI ticket combos for monuments. | H4: Auto/rickshaw overcharging; gem scams.
A5: UDR | B5: Udaipur | C5: 112; 1363 | D5: Generally safe; lakes can be slippery. | E5: Good 4G; UPI accepted. | F5: Modest dress at temples. | G5: Nominal entry fees. | H5: Boat/lake tour touts; bargain.
A6: HMP | B6: Hampi | C6: 112; 1363 | D6: Carry water; heat. | E6: Patchy network across river; cash needed at rural stalls. | F6: Cover shoulders/knees at temples. | G6: ASI tickets for select monuments. | H6: Hampi Bazaar vs Virupapur Gaddi ferry closures; check conditions.
A7: AEL | B7: Ajanta & Ellora Caves | C7: 112; 1363 | D7: Carry water; long day trip to Ajanta. | E7: 4G in Aurangabad; patchy near caves. | F7: Modest dress at Grishneshwar. | G7: Ajanta closed Monday; Ellora closed Tuesday. | H7: Plan around closures; start early.
A8: GOA | B8: Goa | C8: 112; 1363 | D8: Strong currents & jellyfish in monsoon; heed lifeguard flags. | E8: Excellent 4G; UPI everywhere. | F8: Beachwear only on beaches; cover up in churches. | G8: None. | H8: Taxi overcharging; bike-rental damage scams; drink-spiking risk at nightlife.
A9: KER | B9: Kerala Backwaters (Alleppey / Kumarakom / Kochi) | C9: 112; 1363 | D9: Mosquitoes; drink filtered water. | E9: Good 4G; patchy on some backwaters; cash for small boats. | F9: Modest dress at temples. | G9: Houseboat operators should be registered with Kerala Tourism. | H9: Overpriced houseboats; check inclusions.
A10: AND | B10: Andaman & Nicobar Islands | C10: 112; 1363 | D10: Limited hospitals; ferries cancel in storms. | E10: Connectivity patchy (BSNL/Airtel/Jio vary); carry cash - ATMs limited. | F10: Casual beachwear on beaches only. | G10: Indians: no permit; foreigners: RAP on arrival (free) for Andaman; Nicobar largely restricted. | H10: Sea conditions; book ferries early; respect indigenous reserves (no photos).
A11: PON | B11: Pondicherry (Puducherry) | C11: 112; 1363 | D11: Generally safe; mosquitoes. | E11: Good 4G; UPI accepted. | F11: Modest dress at Ashram/Auroville. | G11: Auroville pass free. | H11: Ashram silence rules; touts around Auroville.
A12: VNS | B12: Varanasi | C12: 112; 1363 | D12: Water quality poor in Ganga; drink bottled. | E12: Good 4G; cash preferred in lanes. | F12: Modest dress; remove shoes at temples. | G12: None. | H12: Touts, fake priests, boatmen overcharging; no photos at cremation ghats.
... A16: DAR | B16: Darjeeling | C16: 112; 1363 | D16: Cold nights; road landslides in monsoon. | E16: Good 4G in town; patchy on hills. | F16: Warm layers. | G16: Foreigners visiting Singalila/sensitive border areas need permits. | H16: Taxi overcharging; check jeep unions' fixed rates.

Sheet Circuits
A1: Circuit | B1: Destinations | C1: Ideal days | D1: Best months | E1: Connection notes
A2: Golden Triangle | B2: Delhi - Agra - Jaipur | C2: 5-6 | D2: Oct-Mar | E2: Delhi->Agra ~3.5 h road / ~1 h 45 min train; Agra->Jaipur ~4.5-5 h road (via Fatehpur Sikri); Jaipur->Delhi ~5 h.
A3: Rajasthan Royal Lakes | B3: Jaipur - Udaipur (+ Delhi) | C3: 6-7 | D3: Oct-Mar | E3: Jaipur->Udaipur ~7-9 h by road/bus; Delhi->Udaipur overnight train or 1.5 h flight.
A4: Spiritual North | B4: Delhi - Amritsar - Varanasi | C4: 7-8 | D4: Oct-Mar | E4: Delhi->Amritsar ~6 h Shatabdi; Delhi->Varanasi ~8 h Vande Bharat.
A5: Karnataka Heritage | B5: Mysore - Hampi | C5: 5-6 | D5: Oct-Feb | E5: Mysore->Hampi via Bengaluru overnight bus/train; check current train schedule.
A6: Konkan & Coast | B6: Goa - Hampi | C6: 6-7 | D6: Nov-Feb | E6: Goa->Hospet ~8 h by road / limited rail; Hampi ~13 km from Hospet.
A7: Kerala Backwaters & Kochi | B7: Kochi - Alleppey - Kumarakom | C7: 4-5 | D7: Oct-Mar | E7: Kochi->Alleppey ~2 h; Alleppey->Kumarakom ~1 h by road.
A8: Islands Escape | B8: Port Blair - Havelock - Neil | C8: 6-7 | D8: Nov-Apr | E8: Ferries between islands; book early in peak season.
A9: Ladakh Classic | B9: Leh - Nubra - Pangong | C9: 7-9 | D9: Jun-Sep | E9: Acclimatise 2 days in Leh; Leh->Nubra->Pangong->Leh circuit; Environment fee receipt needed.
