Workbook

Sheet README
A1: India Travel Prototype Dataset
A2: Built from India_Top_500_Tourist_Destinations.xlsx. Only what could be filled reliably is filled – everything else is a ready-to-fill (yellow) column so nothing unverified is presented as fact.
A4: Sheet | B4: Rows with data | C4: What is filled | D4: What still needs to be collected (and where from)
A5: Destination | B5: =COUNTIF(Destination!K2:K501,"Seeded*")+COUNTIF(Destination!K2:K501,"Named only") -> 435 | C5: 435 named cities/areas with state, region, latitude/longitude (approx., 2 decimals), source flag. | D5: 65 slots are unnamed placeholders in your input – they need real destination names. Refine coordinates with OpenStreetMap Nominatim or Google Geocoding.
A6: Place | B6: =COUNTA(Place!A2:A3000) -> 56 | C6: Names + categories for the 10 destinations that had detail in your input file. | D6: Places for the other 425 destinations; exact coordinates. Sources: OpenStreetMap Overpass, Wikidata, Google Places API.
A7: OpeningHours | B7: =COUNTA(OpeningHours!A2:A5000)-COUNTIF(OpeningHours!A2:A5000,"EXAMPLE*") -> 0 | C7: Structure only (one row per place per day). | D7: Real timings. Sources: Google Places API (opening_hours), official site of each attraction, ASI/state tourism pages for monuments.
A8: Activity | B8: =COUNTA(Activity!A2:A3000) -> 20 | C8: Activity names from your input for 10 destinations; interests auto-tagged by keyword (review). | D8: Duration and cost for every activity; activities for the other destinations.
A9: Hotel | B9: =COUNTA(Hotel!A2:A3000) -> 11 | C9: Named properties/brands from your input only. | D9: Price, area, coordinates, check-in/out times. Sources: hotel websites, Booking/Agoda/MakeMyTrip partner APIs, Google Places.
A10: Restaurant | B10: =COUNTA(Restaurant!A2:A5000)-COUNTIF(Restaurant!A2:A5000,"EXAMPLE*") -> 0 | C10: Structure only – your input lists dishes/cuisines, not restaurants. | D10: Restaurant names, cuisine, price, location. Sources: Google Places API, Zomato/Swiggy data partners, OpenStreetMap.
A11: TransportRoute | B11: =COUNTA(TransportRoute!A2:A5000) -> 824 | C11: ~3 nearest road-connected neighbours per destination; distance and duration are formulas (estimates). | D11: Real road distance/time and rail/air/bus options. Sources: OSRM or Google Distance Matrix (road), IRCTC/Indian Railways (rail), airline schedules.
A12: Event | B12: =COUNTA(Event!A2:A5000) -> 29 | C12: 29 well-known recurring events with typical month and approximate duration. | D12: Exact dates for the year you need. Sources: state tourism department calendars, official event sites.
A13: Booking | B13: =COUNTA(Booking!A2:A5000)-COUNTIF(Booking!A2:A5000,"EXAMPLE*") -> 0 | C13: Structure + status dropdowns. Runtime data created by your app. | D13: Generated by the prototype, not collected.
A14: Trip | B14: =COUNTA(Trip!A2:A5000)-COUNTIF(Trip!A2:A5000,"EXAMPLE*") -> 0 | C14: Structure + budget-style dropdown. Runtime data created by your app. | D14: Generated by the prototype, not collected.
A16: Legend
A17: Yellow cell | C17: Empty on purpose – needs verified data
A18: Grey italic row | C18: EXAMPLE row showing the expected format – delete before importing
A19: Blue on yellow | C19: Editable assumption (Assumptions sheet)
A21: Data quality notes
A22: 1. State and region were not in your input for 490 of 500 rows (they read 'India'); they were added here. Region follows the input file's own convention (e.g. Rajasthan = West).
A23: 2. Coordinates were assigned from general geographic knowledge to 2 decimals (~1 km). About half were cross-checked against the GeoNames dataset (flag in coord_source); the rest are marked 'Approximate – verify'.
A24: 3. Some destination entries overlap (e.g. Kashi/Varanasi, Delhi landmarks, 'Heritage' variants) – see the notes column in Destination.
A25: 4. TransportRoute distances are estimates from straight-line distance and the assumptions on the Assumptions sheet; they are not real road distances.
A26: 5. Event months are typical timings; festival dates shift every year, so exact dates are left blank.

Sheet Destination
A1: dest_id | B1: city | C1: state | D1: region | E1: type | F1: latitude | G1: longitude | H1: coord_source | I1: best_season | J1: ideal_stay_days | K1: data_status | L1: notes
A2: D001 | B2: Agra | C2: Uttar Pradesh | D2: North | E2: Heritage | F2: 27.18 | G2: 78.02 | H2: Cross-checked (GeoNames, <40 km) | I2: Oct–Mar | J2: 2 | K2: Seeded (details in source)
A3: D002 | B3: Jaipur | C3: Rajasthan | D3: West | E3: Heritage | F3: 26.91 | G3: 75.79 | H3: Cross-checked (GeoNames, <40 km) | I3: Oct–Mar | J3: 3 | K3: Seeded (details in source)
A4: D003 | B4: Varanasi | C4: Uttar Pradesh | D4: North | E4: Spiritual | F4: 25.32 | G4: 82.99 | H4: Cross-checked (GeoNames, <40 km) | I4: Oct–Mar | J4: 3 | K4: Seeded (details in source)
A5: D004 | B5: Mysuru | C5: Karnataka | D5: South | E5: Heritage | F5: 12.3 | G5: 76.64 | H5: Cross-checked (GeoNames, <40 km) | I5: Oct–Feb | J5: 2 | K5: Seeded (details in source)
A6: D005 | B6: Kochi | C6: Kerala | D6: South | E6: Coastal/Culture | F6: 9.93 | G6: 76.27 | H6: Cross-checked (GeoNames, <40 km) | I6: Oct–Mar | J6: 3 | K6: Seeded (details in source)
A7: D006 | B7: Hampi | C7: Karnataka | D7: South | E7: Heritage/Archaeology | F7: 15.34 | G7: 76.46 | H7: Approximate – verify | I7: Oct–Feb | J7: 3 | K7: Seeded (details in source)
A8: D007 | B8: Munnar | C8: Kerala | D8: South | E8: Hill Station | F8: 10.09 | G8: 77.06 | H8: Cross-checked (GeoNames, <40 km) | I8: Sep–Mar | J8: 3 | K8: Seeded (details in source)
A9: D008 | B9: Rameswaram | C9: Tamil Nadu | D9: South | E9: Pilgrimage/Coastal | F9: 9.29 | G9: 79.31 | H9: Cross-checked (GeoNames, <40 km) | I9: Oct–Mar | J9: 2 | K9: Seeded (details in source)
A10: D009 | B10: Goa | C10: Goa | D10: West | E10: Beach/Leisure | F10: 15.3 | G10: 74 | H10: Cross-checked (GeoNames, <40 km) | I10: Nov–Feb | J10: 4 | K10: Seeded (details in source) | L10: State-level entry; coordinates approximate centre
A11: D010 | B11: Leh | C11: Ladakh | D11: North | E11: Mountain/Adventure | F11: 34.16 | G11: 77.58 | H11: Cross-checked (GeoNames, <40 km) | I11: May–Sep | J11: 5 | K11: Seeded (details in source)
A12: D011 | B12: Delhi | C12: Delhi | D12: North | E12: Tourism Destination | F12: 28.61 | G12: 77.21 | H12: Cross-checked (GeoNames, <40 km) | I12: Season varies | J12: 2 | K12: Named only
A13: D012 | B13: Mathura | C13: Uttar Pradesh | D13: North | E13: Tourism Destination | F13: 27.49 | G13: 77.67 | H13: Cross-checked (GeoNames, <40 km) | I13: Season varies | J13: 2 | K13: Named only
A14: D013 | B14: Vrindavan | C14: Uttar Pradesh | D14: North | E14: Tourism Destination | F14: 27.58 | G14: 77.7 | H14: Cross-checked (GeoNames, <40 km) | I14: Season varies | J14: 2 | K14: Named only
A15: D014 | B15: Lucknow | C15: Uttar Pradesh | D15: North | E15: Tourism Destination | F15: 26.85 | G15: 80.95 | H15: Cross-checked (GeoNames, <40 km) | I15: Season varies | J15: 2 | K15: Named only
A16: D015 | B16: Prayagraj | C16: Uttar Pradesh | D16: North | E16: Tourism Destination | F16: 25.44 | G16: 81.85 | H16: Cross-checked (GeoNames, <40 km) | I16: Season varies | J16: 2 | K16: Named only
A17: D016 | B17: Sarnath | C17: Uttar Pradesh | D17: North | E17: Tourism Destination | F17: 25.38 | G17: 83.02 | H17: Approximate – verify | I17: Season varies | J17: 2 | K17: Named only | L17: Adjacent to Varanasi (about 10 km)
A18: D017 | B18: Jhansi | C18: Uttar Pradesh | D18: North | E18: Tourism Destination | F18: 25.45 | G18: 78.57 | H18: Cross-checked (GeoNames, <40 km) | I18: Season varies | J18: 2 | K18: Named only
A19: D018 | B19: Khajuraho | C19: Madhya Pradesh | D19: Central | E19: Tourism Destination | F19: 24.85 | G19: 79.92 | H19: Cross-checked (GeoNames, <40 km) | I19: Season varies | J19: 2 | K19: Named only
A20: D019 | B20: Orchha | C20: Madhya Pradesh | D20: Central | E20: Tourism Destination | F20: 25.35 | G20: 78.64 | H20: Approximate – verify | I20: Season varies | J20: 2 | K20: Named only
A21: D020 | B21: Gwalior | C21: Madhya Pradesh | D21: Central | E21: Tourism Destination | F21: 26.22 | G21: 78.18 | H21: Cross-checked (GeoNames, <40 km) | I21: Season varies | J21: 2 | K21: Named only
A22: D021 | B22: Amritsar | C22: Punjab | D22: North | E22: Tourism Destination | F22: 31.63 | G22: 74.87 | H22: Cross-checked (GeoNames, <40 km) | I22: Season varies | J22: 2 | K22: Named only
A23: D022 | B23: Chandigarh | C23: Chandigarh | D23: North | E23: Tourism Destination | F23: 30.73 | G23: 76.78 | H23: Cross-checked (GeoNames, <40 km) | I23: Season varies | J23: 2 | K23: Named only
A24: D023 | B24: Shimla | C24: Himachal Pradesh | D24: North | E24: Tourism Destination | F24: 31.1 | G24: 77.17 | H24: Cross-checked (GeoNames, <40 km) | I24: Season varies | J24: 2 | K24: Named only
A25: D024 | B25: Manali | C25: Himachal Pradesh | D25: North | E25: Tourism Destination | F25: 32.24 | G25: 77.19 | H25: Approximate – verify | I25: Season varies | J25: 2 | K25: Named only
A26: D025 | B26: Dharamshala | C26: Himachal Pradesh | D26: North | E26: Tourism Destination | F26: 32.22 | G26: 76.32 | H26: Cross-checked (GeoNames, <40 km) | I26: Season varies | J26: 2 | K26: Named only
A27: D026 | B27: Dalhousie | C27: Himachal Pradesh | D27: North | E27: Tourism Destination | F27: 32.54 | G27: 75.97 | H27: Approximate – verify | I27: Season varies | J27: 2 | K27: Named only
A28: D027 | B28: Rishikesh | C28: Uttarakhand | D28: North | E28: Tourism Destination | F28: 30.09 | G28: 78.27 | H28: Cross-checked (GeoNames, <40 km) | I28: Season varies | J28: 2 | K28: Named only
A29: D028 | B29: Haridwar | C29: Uttarakhand | D29: North | E29: Tourism Destination | F29: 29.95 | G29: 78.16 | H29: Cross-checked (GeoNames, <40 km) | I29: Season varies | J29: 2 | K29: Named only
... A62: D061 | B62: Dausa | C62: Rajasthan | D62: West | E62: Tourism Destination | F62: 26.89 | G62: 76.34 | H62: Cross-checked (GeoNames, <40 km) | I62: Season varies | J62: 2 | K62: Named only
A63: D062 | B63: Shekhawati | C63: Rajasthan | D63: West | E63: Tourism Destination | F63: 27.8 | G63: 75.4 | H63: Approximate – verify | I63: Season varies | J63: 2 | K63: Named only | L63: Region; coordinates approximate centre
A64: D063 | B64: Mandawa | C64: Rajasthan | D64: West | E64: Tourism Destination | F64: 28.06 | G64: 75.15 | H64: Cross-checked (GeoNames, <40 km) | I64: Season varies | J64: 2 | K64: Named only
A65: D064 | B65: Nawalgarh | C65: Rajasthan | D65: West | E65: Tourism Destination | F65: 27.85 | G65: 75.27 | H65: Cross-checked (GeoNames, <40 km) | I65: Season varies | J65: 2 | K65: Named only
A66: D065 | B66: Barmer | C66: Rajasthan | D66: West | E66: Tourism Destination | F66: 25.75 | G66: 71.39 | H66: Cross-checked (GeoNames, <40 km) | I66: Season varies | J66: 2 | K66: Named only
A67: D066 | B67: Nagaur | C67: Rajasthan | D67: West | E67: Tourism Destination | F67: 27.2 | G67: 73.73 | H67: Cross-checked (GeoNames, <40 km) | I67: Season varies | J67: 2 | K67: Named only
A68: D067 | B68: Kumbhalgarh | C68: Rajasthan | D68: West | E68: Tourism Destination | F68: 25.15 | G68: 73.58 | H68: Approximate – verify | I68: Season varies | J68: 2 | K68: Named only
A69: D068 | B69: Ranakpur | C69: Rajasthan | D69: West | E69: Tourism Destination | F69: 25.12 | G69: 73.47 | H69: Approximate – verify | I69: Season varies | J69: 2 | K69: Named only
A70: D069 | B70: Nathdwara | C70: Rajasthan | D70: West | E70: Tourism Destination | F70: 24.94 | G70: 73.82 | H70: Cross-checked (GeoNames, <40 km) | I70: Season varies | J70: 2 | K70: Named only
A71: D070 | B71: Neemrana | C71: Rajasthan | D71: West | E71: Tourism Destination | F71: 27.99 | G71: 76.38 | H71: Approximate – verify | I71: Season varies | J71: 2 | K71: Named only
A72: D071 | B72: Osian | C72: Rajasthan | D72: West | E72: Tourism Destination | F72: 26.72 | G72: 72.9 | H72: Approximate – verify | I72: Season varies | J72: 2 | K72: Named only
...

Sheet Place
A1: place_id | B1: dest_id | C1: city | D1: name | E1: category | F1: latitude | G1: longitude | H1: source | I1: verified
A2: P0001 | B2: D001 | C2: =IFERROR(INDEX(Destination!$B$2:$B$501,MATCH(B2,Destination!$A$2:$A$501,0)),"") -> Agra | D2: Mankameshwar Temple | E2: Religious | H2: Input file: Temples / Religious
A3: P0002 | B3: D001 | C3: =IFERROR(INDEX(Destination!$B$2:$B$501,MATCH(B3,Destination!$A$2:$A$501,0)),"") -> Agra | D3: Agra Fort | E3: Heritage | H3: Input file: Monuments / Heritage
A4: P0003 | B4: D001 | C4: =IFERROR(INDEX(Destination!$B$2:$B$501,MATCH(B4,Destination!$A$2:$A$501,0)),"") -> Agra | D4: Itmad-ud-Daulah | E4: Heritage | H4: Input file: Monuments / Heritage
A5: P0004 | B5: D001 | C5: =IFERROR(INDEX(Destination!$B$2:$B$501,MATCH(B5,Destination!$A$2:$A$501,0)),"") -> Agra | D5: Yamuna riverfront | E5: Nature | H5: Input file: Nature
A6: P0005 | B6: D001 | C6: =IFERROR(INDEX(Destination!$B$2:$B$501,MATCH(B6,Destination!$A$2:$A$501,0)),"") -> Agra | D6: Taj Mahal | E6: Attraction | H6: Input file: Famous Attractions
A7: P0006 | B7: D001 | C7: =IFERROR(INDEX(Destination!$B$2:$B$501,MATCH(B7,Destination!$A$2:$A$501,0)),"") -> Agra | D7: Mehtab Bagh | E7: Attraction | H7: Input file: Famous Attractions
A8: P0007 | B8: D002 | C8: =IFERROR(INDEX(Destination!$B$2:$B$501,MATCH(B8,Destination!$A$2:$A$501,0)),"") -> Jaipur | D8: Govind Dev Ji | E8: Religious | H8: Input file: Temples / Religious
A9: P0008 | B9: D002 | C9: =IFERROR(INDEX(Destination!$B$2:$B$501,MATCH(B9,Destination!$A$2:$A$501,0)),"") -> Jaipur | D9: Birla Mandir | E9: Religious | H9: Input file: Temples / Religious
A10: P0009 | B10: D002 | C10: =IFERROR(INDEX(Destination!$B$2:$B$501,MATCH(B10,Destination!$A$2:$A$501,0)),"") -> Jaipur | D10: Jantar Mantar | E10: Heritage | H10: Input file: Monuments / Heritage
A11: P0010 | B11: D002 | C11: =IFERROR(INDEX(Destination!$B$2:$B$501,MATCH(B11,Destination!$A$2:$A$501,0)),"") -> Jaipur | D11: City Palace | E11: Heritage | H11: Input file: Monuments / Heritage
A12: P0011 | B12: D002 | C12: =IFERROR(INDEX(Destination!$B$2:$B$501,MATCH(B12,Destination!$A$2:$A$501,0)),"") -> Jaipur | D12: Amber Fort | E12: Attraction | H12: Input file: Famous Attractions
A13: P0012 | B13: D002 | C13: =IFERROR(INDEX(Destination!$B$2:$B$501,MATCH(B13,Destination!$A$2:$A$501,0)),"") -> Jaipur | D13: Hawa Mahal | E13: Attraction | H13: Input file: Famous Attractions
... A57: P0056 | B57: D010 | C57: =IFERROR(INDEX(Destination!$B$2:$B$501,MATCH(B57,Destination!$A$2:$A$501,0)),"") -> Leh | D57: Nubra Valley | E57: Attraction | H57: Input file: Famous Attractions

Sheet OpeningHours
A1: hours_id | B1: place_id | C1: place_name | D1: day | E1: open_time | F1: close_time | G1: is_closed | H1: notes
A2: EXAMPLE | B2: P0001 | C2: Example place – delete this row | D2: Mon | E2: 09:00 | F2: 17:00 | G2: N | H2: Use 24-hour HH:MM; one row per place per day
C3: =IFERROR(INDEX(Place!$D$2:$D$3000,MATCH(B3,Place!$A$2:$A$3000,0)),"")
C4: =IFERROR(INDEX(Place!$D$2:$D$3000,MATCH(B4,Place!$A$2:$A$3000,0)),"")
C5: =IFERROR(INDEX(Place!$D$2:$D$3000,MATCH(B5,Place!$A$2:$A$3000,0)),"")
C6: =IFERROR(INDEX(Place!$D$2:$D$3000,MATCH(B6,Place!$A$2:$A$3000,0)),"")
C7: =IFERROR(INDEX(Place!$D$2:$D$3000,MATCH(B7,Place!$A$2:$A$3000,0)),"")

Sheet Activity
A1: activity_id | B1: dest_id | C1: city | D1: name | E1: duration_hrs | F1: cost_inr | G1: interests (auto-tagged – review) | H1: source
A2: A0001 | B2: D001 | C2: =IFERROR(INDEX(Destination!$B$2:$B$501,MATCH(B2,Destination!$A$2:$A$501,0)),"") -> Agra | D2: Taj Mahal sunrise | G2: Sightseeing | H2: Input file: Activities
A3: A0002 | B3: D001 | C3: =IFERROR(INDEX(Destination!$B$2:$B$501,MATCH(B3,Destination!$A$2:$A$501,0)),"") -> Agra | D3: Heritage walk | G3: Heritage | H3: Input file: Activities
A4: A0003 | B4: D002 | C4: =IFERROR(INDEX(Destination!$B$2:$B$501,MATCH(B4,Destination!$A$2:$A$501,0)),"") -> Jaipur | D4: Fort tour | G4: Heritage | H4: Input file: Activities
A5: A0004 | B5: D002 | C5: =IFERROR(INDEX(Destination!$B$2:$B$501,MATCH(B5,Destination!$A$2:$A$501,0)),"") -> Jaipur | D5: Food walk | G5: Food | H5: Input file: Activities
A6: A0005 | B6: D003 | C6: =IFERROR(INDEX(Destination!$B$2:$B$501,MATCH(B6,Destination!$A$2:$A$501,0)),"") -> Varanasi | D6: Ganga Aarti | G6: Spiritual | H6: Input file: Activities
A7: A0006 | B7: D003 | C7: =IFERROR(INDEX(Destination!$B$2:$B$501,MATCH(B7,Destination!$A$2:$A$501,0)),"") -> Varanasi | D7: Boat ride | G7: Nature | H7: Input file: Activities
A8: A0007 | B8: D004 | C8: =IFERROR(INDEX(Destination!$B$2:$B$501,MATCH(B8,Destination!$A$2:$A$501,0)),"") -> Mysuru | D8: Palace tour | G8: Heritage | H8: Input file: Activities
A9: A0008 | B9: D004 | C9: =IFERROR(INDEX(Destination!$B$2:$B$501,MATCH(B9,Destination!$A$2:$A$501,0)),"") -> Mysuru | D9: Heritage walk | G9: Heritage | H9: Input file: Activities
A10: A0009 | B10: D005 | C10: =IFERROR(INDEX(Destination!$B$2:$B$501,MATCH(B10,Destination!$A$2:$A$501,0)),"") -> Kochi | D10: Heritage walk | G10: Heritage | H10: Input file: Activities
A11: A0010 | B11: D005 | C11: =IFERROR(INDEX(Destination!$B$2:$B$501,MATCH(B11,Destination!$A$2:$A$501,0)),"") -> Kochi | D11: Boat ride | G11: Nature | H11: Input file: Activities
A12: A0011 | B12: D006 | C12: =IFERROR(INDEX(Destination!$B$2:$B$501,MATCH(B12,Destination!$A$2:$A$501,0)),"") -> Hampi | D12: Cycling | G12: Adventure | H12: Input file: Activities
A13: A0012 | B13: D006 | C13: =IFERROR(INDEX(Destination!$B$2:$B$501,MATCH(B13,Destination!$A$2:$A$501,0)),"") -> Hampi | D13: Ruins exploration | G13: Heritage | H13: Input file: Activities
... A21: A0020 | B21: D010 | C21: =IFERROR(INDEX(Destination!$B$2:$B$501,MATCH(B21,Destination!$A$2:$A$501,0)),"") -> Leh | D21: Road trips | G21: Adventure | H21: Input file: Activities

Sheet Hotel
A1: hotel_id | B1: dest_id | C1: city | D1: name | E1: price_per_night_inr | F1: location_area | G1: latitude | H1: longitude | I1: check_in | J1: check_out | K1: source
A2: H0001 | B2: D001 | C2: =IFERROR(INDEX(Destination!$B$2:$B$501,MATCH(B2,Destination!$A$2:$A$501,0)),"") -> Agra | D2: The Oberoi Amarvilas | K2: Input file (name as given; not independently verified)
A3: H0002 | B3: D001 | C3: =IFERROR(INDEX(Destination!$B$2:$B$501,MATCH(B3,Destination!$A$2:$A$501,0)),"") -> Agra | D3: ITC Mughal | K3: Input file (name as given; not independently verified)
A4: H0003 | B4: D002 | C4: =IFERROR(INDEX(Destination!$B$2:$B$501,MATCH(B4,Destination!$A$2:$A$501,0)),"") -> Jaipur | D4: Rambagh Palace | K4: Input file (name as given; not independently verified)
A5: H0004 | B5: D002 | C5: =IFERROR(INDEX(Destination!$B$2:$B$501,MATCH(B5,Destination!$A$2:$A$501,0)),"") -> Jaipur | D5: ITC Rajputana | K5: Input file (name as given; not independently verified)
A6: H0005 | B6: D003 | C6: =IFERROR(INDEX(Destination!$B$2:$B$501,MATCH(B6,Destination!$A$2:$A$501,0)),"") -> Varanasi | D6: Taj Ganges | K6: Input file (name as given; not independently verified)
A7: H0006 | B7: D003 | C7: =IFERROR(INDEX(Destination!$B$2:$B$501,MATCH(B7,Destination!$A$2:$A$501,0)),"") -> Varanasi | D7: BrijRama Palace | K7: Input file (name as given; not independently verified)
A8: H0007 | B8: D004 | C8: =IFERROR(INDEX(Destination!$B$2:$B$501,MATCH(B8,Destination!$A$2:$A$501,0)),"") -> Mysuru | D8: Lalitha Mahal Palace | K8: Input file (name as given; not independently verified)
A9: H0008 | B9: D004 | C9: =IFERROR(INDEX(Destination!$B$2:$B$501,MATCH(B9,Destination!$A$2:$A$501,0)),"") -> Mysuru | D9: Radisson | K9: Input file (brand/chain only – confirm exact property)
A10: H0009 | B10: D005 | C10: =IFERROR(INDEX(Destination!$B$2:$B$501,MATCH(B10,Destination!$A$2:$A$501,0)),"") -> Kochi | D10: Grand Hyatt | K10: Input file (brand/chain only – confirm exact property)
A11: H0010 | B11: D005 | C11: =IFERROR(INDEX(Destination!$B$2:$B$501,MATCH(B11,Destination!$A$2:$A$501,0)),"") -> Kochi | D11: Brunton Boatyard | K11: Input file (name as given; not independently verified)
A12: H0011 | B12: D008 | C12: =IFERROR(INDEX(Destination!$B$2:$B$501,MATCH(B12,Destination!$A$2:$A$501,0)),"") -> Rameswaram | D12: Daiwik Hotels | K12: Input file (brand/chain only – confirm exact property)

Sheet Restaurant
A1: restaurant_id | B1: dest_id | C1: city | D1: name | E1: cuisine | F1: avg_cost_for_two_inr | G1: location_area | H1: latitude | I1: longitude | J1: source
A2: EXAMPLE | B2: D001 | C2: Agra | D2: Example Restaurant – delete this row | E2: Mughlai | F2: 800 | G2: Near Taj Ganj | H2: 27.165 | I2: 78.042 | J2: Your source

Sheet TransportRoute
A1: route_id | B1: from_dest_id | C1: from_city | D1: to_dest_id | E1: to_city | F1: mode | G1: from_lat | H1: from_lon | I1: to_lat | J1: to_lon | K1: straight_line_km | L1: est_road_km | M1: est_duration_hrs | N1: source
A2: T0001 | B2: D001 | C2: =IFERROR(INDEX(Destination!$B$2:$B$501,MATCH(B2,Destination!$A$2:$A$501,0)),"") -> Agra | D2: D012 | E2: =IFERROR(INDEX(Destination!$B$2:$B$501,MATCH(D2,Destination!$A$2:$A$501,0)),"") -> Mathura | F2: Road (estimate) | G2: =INDEX(Destination!$F$2:$F$501,MATCH(B2,Destination!$A$2:$A$501,0)) -> 27.18 | H2: =INDEX(Destination!$G$2:$G$501,MATCH(B2,Destination!$A$2:$A$501,0)) -> 78.02 | I2: =INDEX(Destination!$F$2:$F$501,MATCH(D2,Destination!$A$2:$A$501,0)) -> 27.49 | J2: =INDEX(Destination!$G$2:$G$501,MATCH(D2,Destination!$A$2:$A$501,0)) -> 77.67 | K2: =Assumptions!$B$2*2*ASIN(SQRT(SIN(RADIANS(I2-G2)/2)^2+COS(RADIANS(G2))*COS(RADIANS(I2))*SIN(RADIANS(J2-H2)/2)^2)) -> 48.82071 | L2: =K2*Assumptions!$B$3 -> 63.466923 | M2: =L2/Assumptions!$B$4 -> 1.4103761 | N2: Derived: haversine × circuity ÷ speed (see Assumptions)
A3: T0002 | B3: D001 | C3: =IFERROR(INDEX(Destination!$B$2:$B$501,MATCH(B3,Destination!$A$2:$A$501,0)),"") -> Agra | D3: D013 | E3: =IFERROR(INDEX(Destination!$B$2:$B$501,MATCH(D3,Destination!$A$2:$A$501,0)),"") -> Vrindavan | F3: Road (estimate) | G3: =INDEX(Destination!$F$2:$F$501,MATCH(B3,Destination!$A$2:$A$501,0)) -> 27.18 | H3: =INDEX(Destination!$G$2:$G$501,MATCH(B3,Destination!$A$2:$A$501,0)) -> 78.02 | I3: =INDEX(Destination!$F$2:$F$501,MATCH(D3,Destination!$A$2:$A$501,0)) -> 27.58 | J3: =INDEX(Destination!$G$2:$G$501,MATCH(D3,Destination!$A$2:$A$501,0)) -> 77.7 | K3: =Assumptions!$B$2*2*ASIN(SQRT(SIN(RADIANS(I3-G3)/2)^2+COS(RADIANS(G3))*COS(RADIANS(I3))*SIN(RADIANS(J3-H3)/2)^2)) -> 54.558298 | L3: =K3*Assumptions!$B$3 -> 70.925787 | M3: =L3/Assumptions!$B$4 -> 1.5761286 | N3: Derived: haversine × circuity ÷ speed (see Assumptions)
A4: T0003 | B4: D001 | C4: =IFERROR(INDEX(Destination!$B$2:$B$501,MATCH(B4,Destination!$A$2:$A$501,0)),"") -> Agra | D4: D060 | E4: =IFERROR(INDEX(Destination!$B$2:$B$501,MATCH(D4,Destination!$A$2:$A$501,0)),"") -> Bharatpur | F4: Road (estimate) | G4: =INDEX(Destination!$F$2:$F$501,MATCH(B4,Destination!$A$2:$A$501,0)) -> 27.18 | H4: =INDEX(Destination!$G$2:$G$501,MATCH(B4,Destination!$A$2:$A$501,0)) -> 78.02 | I4: =INDEX(Destination!$F$2:$F$501,MATCH(D4,Destination!$A$2:$A$501,0)) -> 27.22 | J4: =INDEX(Destination!$G$2:$G$501,MATCH(D4,Destination!$A$2:$A$501,0)) -> 77.49 | K4: =Assumptions!$B$2*2*ASIN(SQRT(SIN(RADIANS(I4-G4)/2)^2+COS(RADIANS(G4))*COS(RADIANS(I4))*SIN(RADIANS(J4-H4)/2)^2)) -> 52.604582 | L4: =K4*Assumptions!$B$3 -> 68.385957 | M4: =L4/Assumptions!$B$4 -> 1.5196879 | N4: Derived: haversine × circuity ÷ speed (see Assumptions)
A5: T0004 | B5: D001 | C5: =IFERROR(INDEX(Destination!$B$2:$B$501,MATCH(B5,Destination!$A$2:$A$501,0)),"") -> Agra | D5: D072 | E5: =IFERROR(INDEX(Destination!$B$2:$B$501,MATCH(D5,Destination!$A$2:$A$501,0)),"") -> Dholpur | F5: Road (estimate) | G5: =INDEX(Destination!$F$2:$F$501,MATCH(B5,Destination!$A$2:$A$501,0)) -> 27.18 | H5: =INDEX(Destination!$G$2:$G$501,MATCH(B5,Destination!$A$2:$A$501,0)) -> 78.02 | I5: =INDEX(Destination!$F$2:$F$501,MATCH(D5,Destination!$A$2:$A$501,0)) -> 26.7 | J5: =INDEX(Destination!$G$2:$G$501,MATCH(D5,Destination!$A$2:$A$501,0)) -> 77.89 | K5: =Assumptions!$B$2*2*ASIN(SQRT(SIN(RADIANS(I5-G5)/2)^2+COS(RADIANS(G5))*COS(RADIANS(I5))*SIN(RADIANS(J5-H5)/2)^2)) -> 54.907212 | L5: =K5*Assumptions!$B$3 -> 71.379375 | M5: =L5/Assumptions!$B$4 -> 1.5862083 | N5: Derived: haversine × circuity ÷ speed (see Assumptions)
A6: T0005 | B6: D001 | C6: =IFERROR(INDEX(Destination!$B$2:$B$501,MATCH(B6,Destination!$A$2:$A$501,0)),"") -> Agra | D6: D431 | E6: =IFERROR(INDEX(Destination!$B$2:$B$501,MATCH(D6,Destination!$A$2:$A$501,0)),"") -> Fatehpur Sikri | F6: Road (estimate) | G6: =INDEX(Destination!$F$2:$F$501,MATCH(B6,Destination!$A$2:$A$501,0)) -> 27.18 | H6: =INDEX(Destination!$G$2:$G$501,MATCH(B6,Destination!$A$2:$A$501,0)) -> 78.02 | I6: =INDEX(Destination!$F$2:$F$501,MATCH(D6,Destination!$A$2:$A$501,0)) -> 27.09 | J6: =INDEX(Destination!$G$2:$G$501,MATCH(D6,Destination!$A$2:$A$501,0)) -> 77.67 | K6: =Assumptions!$B$2*2*ASIN(SQRT(SIN(RADIANS(I6-G6)/2)^2+COS(RADIANS(G6))*COS(RADIANS(I6))*SIN(RADIANS(J6-H6)/2)^2)) -> 36.051487 | L6: =K6*Assumptions!$B$3 -> 46.866933 | M6: =L6/Assumptions!$B$4 -> 1.0414874 | N6: Derived: haversine × circuity ÷ speed (see Assumptions)
A7: T0006 | B7: D002 | C7: =IFERROR(INDEX(Destination!$B$2:$B$501,MATCH(B7,Destination!$A$2:$A$501,0)),"") -> Jaipur | D7: D061 | E7: =IFERROR(INDEX(Destination!$B$2:$B$501,MATCH(D7,Destination!$A$2:$A$501,0)),"") -> Dausa | F7: Road (estimate) | G7: =INDEX(Destination!$F$2:$F$501,MATCH(B7,Destination!$A$2:$A$501,0)) -> 26.91 | H7: =INDEX(Destination!$G$2:$G$501,MATCH(B7,Destination!$A$2:$A$501,0)) -> 75.79 | I7: =INDEX(Destination!$F$2:$F$501,MATCH(D7,Destination!$A$2:$A$501,0)) -> 26.89 | J7: =INDEX(Destination!$G$2:$G$501,MATCH(D7,Destination!$A$2:$A$501,0)) -> 76.34 | K7: =Assumptions!$B$2*2*ASIN(SQRT(SIN(RADIANS(I7-G7)/2)^2+COS(RADIANS(G7))*COS(RADIANS(I7))*SIN(RADIANS(J7-H7)/2)^2)) -> 54.585127 | L7: =K7*Assumptions!$B$3 -> 70.960665 | M7: =L7/Assumptions!$B$4 -> 1.5769037 | N7: Derived: haversine × circuity ÷ speed (see Assumptions)
A8: T0007 | B8: D002 | C8: =IFERROR(INDEX(Destination!$B$2:$B$501,MATCH(B8,Destination!$A$2:$A$501,0)),"") -> Jaipur | D8: D062 | E8: =IFERROR(INDEX(Destination!$B$2:$B$501,MATCH(D8,Destination!$A$2:$A$501,0)),"") -> Shekhawati | F8: Road (estimate) | G8: =INDEX(Destination!$F$2:$F$501,MATCH(B8,Destination!$A$2:$A$501,0)) -> 26.91 | H8: =INDEX(Destination!$G$2:$G$501,MATCH(B8,Destination!$A$2:$A$501,0)) -> 75.79 | I8: =INDEX(Destination!$F$2:$F$501,MATCH(D8,Destination!$A$2:$A$501,0)) -> 27.8 | J8: =INDEX(Destination!$G$2:$G$501,MATCH(D8,Destination!$A$2:$A$501,0)) -> 75.4 | K8: =Assumptions!$B$2*2*ASIN(SQRT(SIN(RADIANS(I8-G8)/2)^2+COS(RADIANS(G8))*COS(RADIANS(I8))*SIN(RADIANS(J8-H8)/2)^2)) -> 106.1944 | L8: =K8*Assumptions!$B$3 -> 138.05272 | M8: =L8/Assumptions!$B$4 -> 3.0678383 | N8: Derived: haversine × circuity ÷ speed (see Assumptions)
A9: T0008 | B9: D002 | C9: =IFERROR(INDEX(Destination!$B$2:$B$501,MATCH(B9,Destination!$A$2:$A$501,0)),"") -> Jaipur | D9: D074 | E9: =IFERROR(INDEX(Destination!$B$2:$B$501,MATCH(D9,Destination!$A$2:$A$501,0)),"") -> Tonk | F9: Road (estimate) | G9: =INDEX(Destination!$F$2:$F$501,MATCH(B9,Destination!$A$2:$A$501,0)) -> 26.91 | H9: =INDEX(Destination!$G$2:$G$501,MATCH(B9,Destination!$A$2:$A$501,0)) -> 75.79 | I9: =INDEX(Destination!$F$2:$F$501,MATCH(D9,Destination!$A$2:$A$501,0)) -> 26.17 | J9: =INDEX(Destination!$G$2:$G$501,MATCH(D9,Destination!$A$2:$A$501,0)) -> 75.79 | K9: =Assumptions!$B$2*2*ASIN(SQRT(SIN(RADIANS(I9-G9)/2)^2+COS(RADIANS(G9))*COS(RADIANS(I9))*SIN(RADIANS(J9-H9)/2)^2)) -> 82.284246 | L9: =K9*Assumptions!$B$3 -> 106.96952 | M9: =L9/Assumptions!$B$4 -> 2.3771004 | N9: Derived: haversine × circuity ÷ speed (see Assumptions)
A10: T0009 | B10: D003 | C10: =IFERROR(INDEX(Destination!$B$2:$B$501,MATCH(B10,Destination!$A$2:$A$501,0)),"") -> Varanasi | D10: D015 | E10: =IFERROR(INDEX(Destination!$B$2:$B$501,MATCH(D10,Destination!$A$2:$A$501,0)),"") -> Prayagraj | F10: Road (estimate) | G10: =INDEX(Destination!$F$2:$F$501,MATCH(B10,Destination!$A$2:$A$501,0)) -> 25.32 | H10: =INDEX(Destination!$G$2:$G$501,MATCH(B10,Destination!$A$2:$A$501,0)) -> 82.99 | I10: =INDEX(Destination!$F$2:$F$501,MATCH(D10,Destination!$A$2:$A$501,0)) -> 25.44 | J10: =INDEX(Destination!$G$2:$G$501,MATCH(D10,Destination!$A$2:$A$501,0)) -> 81.85 | K10: =Assumptions!$B$2*2*ASIN(SQRT(SIN(RADIANS(I10-G10)/2)^2+COS(RADIANS(G10))*COS(RADIANS(I10))*SIN(RADIANS(J10-H10)/2)^2)) -> 115.30206 | L10: =K10*Assumptions!$B$3 -> 149.89268 | M10: =L10/Assumptions!$B$4 -> 3.3309485 | N10: Derived: haversine × circuity ÷ speed (see Assumptions)
A11: T0010 | B11: D003 | C11: =IFERROR(INDEX(Destination!$B$2:$B$501,MATCH(B11,Destination!$A$2:$A$501,0)),"") -> Varanasi | D11: D301 | E11: =IFERROR(INDEX(Destination!$B$2:$B$501,MATCH(D11,Destination!$A$2:$A$501,0)),"") -> Betla | F11: Road (estimate) | G11: =INDEX(Destination!$F$2:$F$501,MATCH(B11,Destination!$A$2:$A$501,0)) -> 25.32 | H11: =INDEX(Destination!$G$2:$G$501,MATCH(B11,Destination!$A$2:$A$501,0)) -> 82.99 | I11: =INDEX(Destination!$F$2:$F$501,MATCH(D11,Destination!$A$2:$A$501,0)) -> 23.89 | J11: =INDEX(Destination!$G$2:$G$501,MATCH(D11,Destination!$A$2:$A$501,0)) -> 84.19 | K11: =Assumptions!$B$2*2*ASIN(SQRT(SIN(RADIANS(I11-G11)/2)^2+COS(RADIANS(G11))*COS(RADIANS(I11))*SIN(RADIANS(J11-H11)/2)^2)) -> 200.0013 | L11: =K11*Assumptions!$B$3 -> 260.00169 | M11: =L11/Assumptions!$B$4 -> 5.7778154 | N11: Derived: haversine × circuity ÷ speed (see Assumptions)
A12: T0011 | B12: D003 | C12: =IFERROR(INDEX(Destination!$B$2:$B$501,MATCH(B12,Destination!$A$2:$A$501,0)),"") -> Varanasi | D12: D429 | E12: =IFERROR(INDEX(Destination!$B$2:$B$501,MATCH(D12,Destination!$A$2:$A$501,0)),"") -> Ayodhya | F12: Road (estimate) | G12: =INDEX(Destination!$F$2:$F$501,MATCH(B12,Destination!$A$2:$A$501,0)) -> 25.32 | H12: =INDEX(Destination!$G$2:$G$501,MATCH(B12,Destination!$A$2:$A$501,0)) -> 82.99 | I12: =INDEX(Destination!$F$2:$F$501,MATCH(D12,Destination!$A$2:$A$501,0)) -> 26.8 | J12: =INDEX(Destination!$G$2:$G$501,MATCH(D12,Destination!$A$2:$A$501,0)) -> 82.2 | K12: =Assumptions!$B$2*2*ASIN(SQRT(SIN(RADIANS(I12-G12)/2)^2+COS(RADIANS(G12))*COS(RADIANS(I12))*SIN(RADIANS(J12-H12)/2)^2)) -> 182.50885 | L12: =K12*Assumptions!$B$3 -> 237.26151 | M12: =L12/Assumptions!$B$4 -> 5.272478 | N12: Derived: haversine × circuity ÷ speed (see Assumptions)
A13: T0012 | B13: D004 | C13: =IFERROR(INDEX(Destination!$B$2:$B$501,MATCH(B13,Destination!$A$2:$A$501,0)),"") -> Mysuru | D13: D149 | E13: =IFERROR(INDEX(Destination!$B$2:$B$501,MATCH(D13,Destination!$A$2:$A$501,0)),"") -> Kabini | F13: Road (estimate) | G13: =INDEX(Destination!$F$2:$F$501,MATCH(B13,Destination!$A$2:$A$501,0)) -> 12.3 | H13: =INDEX(Destination!$G$2:$G$501,MATCH(B13,Destination!$A$2:$A$501,0)) -> 76.64 | I13: =INDEX(Destination!$F$2:$F$501,MATCH(D13,Destination!$A$2:$A$501,0)) -> 11.99 | J13: =INDEX(Destination!$G$2:$G$501,MATCH(D13,Destination!$A$2:$A$501,0)) -> 76.35 | K13: =Assumptions!$B$2*2*ASIN(SQRT(SIN(RADIANS(I13-G13)/2)^2+COS(RADIANS(G13))*COS(RADIANS(I13))*SIN(RADIANS(J13-H13)/2)^2)) -> 46.7121 | L13: =K13*Assumptions!$B$3 -> 60.72573 | M13: =L13/Assumptions!$B$4 -> 1.3494607 | N13: Derived: haversine × circuity ÷ speed (see Assumptions)
... A825: T0824 | B825: D429 | C825: =IFERROR(INDEX(Destination!$B$2:$B$501,MATCH(B825,Destination!$A$2:$A$501,0)),"") -> Ayodhya | D825: D430 | E825: =IFERROR(INDEX(Destination!$B$2:$B$501,MATCH(D825,Destination!$A$2:$A$501,0)),"") -> Kashi | F825: Road (estimate) | G825: =INDEX(Destination!$F$2:$F$501,MATCH(B825,Destination!$A$2:$A$501,0)) -> 26.8 | H825: =INDEX(Destination!$G$2:$G$501,MATCH(B825,Destination!$A$2:$A$501,0)) -> 82.2 | I825: =INDEX(Destination!$F$2:$F$501,MATCH(D825,Destination!$A$2:$A$501,0)) -> 25.31 | J825: =INDEX(Destination!$G$2:$G$501,MATCH(D825,Destination!$A$2:$A$501,0)) -> 83.01 | K825: =Assumptions!$B$2*2*ASIN(SQRT(SIN(RADIANS(I825-G825)/2)^2+COS(RADIANS(G825))*COS(RADIANS(I825))*SIN(RADIANS(J825-H825)/2)^2)) -> 184.38145 | L825: =K825*Assumptions!$B$3 -> 239.69588 | M825: =L825/Assumptions!$B$4 -> 5.3265751 | N825: Derived: haversine × circuity ÷ speed (see Assumptions)

Sheet Event
A1: event_id | B1: name | C1: dest_id | D1: city | E1: venue_or_area | F1: latitude | G1: longitude | H1: typical_month | I1: start_date | J1: end_date | K1: duration_days_approx | L1: event_type | M1: confidence
A2: E0001 | B2: Pushkar Camel Fair | C2: D050 | D2: =IFERROR(INDEX(Destination!$B$2:$B$501,MATCH(C2,Destination!$A$2:$A$501,0)),"") -> Pushkar | E2: Pushkar Lake & fairground | F2: =INDEX(Destination!$F$2:$F$501,MATCH(C2,Destination!$A$2:$A$501,0)) -> 26.49 | G2: =INDEX(Destination!$G$2:$G$501,MATCH(C2,Destination!$A$2:$A$501,0)) -> 74.55 | H2: Nov | K2: 7 | L2: Fair | M2: Medium – typical timing; confirm exact dates each year
A3: E0002 | B3: Dev Deepawali | C3: D003 | D3: =IFERROR(INDEX(Destination!$B$2:$B$501,MATCH(C3,Destination!$A$2:$A$501,0)),"") -> Varanasi | E3: Ganga ghats | F3: =INDEX(Destination!$F$2:$F$501,MATCH(C3,Destination!$A$2:$A$501,0)) -> 25.32 | G3: =INDEX(Destination!$G$2:$G$501,MATCH(C3,Destination!$A$2:$A$501,0)) -> 82.99 | H3: Nov | K3: 1 | L3: Religious | M3: Medium – typical timing; confirm exact dates each year
A4: E0003 | B4: Jaipur Literature Festival | C4: D002 | D4: =IFERROR(INDEX(Destination!$B$2:$B$501,MATCH(C4,Destination!$A$2:$A$501,0)),"") -> Jaipur | F4: =INDEX(Destination!$F$2:$F$501,MATCH(C4,Destination!$A$2:$A$501,0)) -> 26.91 | G4: =INDEX(Destination!$G$2:$G$501,MATCH(C4,Destination!$A$2:$A$501,0)) -> 75.79 | H4: Jan | K4: 5 | L4: Literary | M4: Medium – typical timing; confirm exact dates each year
A5: E0004 | B5: Hornbill Festival | C5: D354 | D5: =IFERROR(INDEX(Destination!$B$2:$B$501,MATCH(C5,Destination!$A$2:$A$501,0)),"") -> Kohima | E5: Kisama Heritage Village | F5: =INDEX(Destination!$F$2:$F$501,MATCH(C5,Destination!$A$2:$A$501,0)) -> 25.67 | G5: =INDEX(Destination!$G$2:$G$501,MATCH(C5,Destination!$A$2:$A$501,0)) -> 94.11 | H5: Dec | K5: 10 | L5: Cultural | M5: Medium – typical timing; confirm exact dates each year
A6: E0005 | B6: Rath Yatra | C6: D257 | D6: =IFERROR(INDEX(Destination!$B$2:$B$501,MATCH(C6,Destination!$A$2:$A$501,0)),"") -> Puri | E6: Jagannath Temple / Grand Road | F6: =INDEX(Destination!$F$2:$F$501,MATCH(C6,Destination!$A$2:$A$501,0)) -> 19.81 | G6: =INDEX(Destination!$G$2:$G$501,MATCH(C6,Destination!$A$2:$A$501,0)) -> 85.83 | H6: Jun–Jul | K6: 9 | L6: Religious | M6: Medium – typical timing; confirm exact dates each year
A7: E0006 | B7: Mysuru Dasara | C7: D004 | D7: =IFERROR(INDEX(Destination!$B$2:$B$501,MATCH(C7,Destination!$A$2:$A$501,0)),"") -> Mysuru | E7: Mysuru Palace | F7: =INDEX(Destination!$F$2:$F$501,MATCH(C7,Destination!$A$2:$A$501,0)) -> 12.3 | G7: =INDEX(Destination!$G$2:$G$501,MATCH(C7,Destination!$A$2:$A$501,0)) -> 76.64 | H7: Sep–Oct | K7: 10 | L7: Cultural | M7: Medium – typical timing; confirm exact dates each year
A8: E0007 | B8: Thrissur Pooram | C8: D220 | D8: =IFERROR(INDEX(Destination!$B$2:$B$501,MATCH(C8,Destination!$A$2:$A$501,0)),"") -> Thrissur | E8: Vadakkunnathan Temple | F8: =INDEX(Destination!$F$2:$F$501,MATCH(C8,Destination!$A$2:$A$501,0)) -> 10.53 | G8: =INDEX(Destination!$G$2:$G$501,MATCH(C8,Destination!$A$2:$A$501,0)) -> 76.21 | H8: Apr–May | K8: 1 | L8: Religious | M8: Medium – typical timing; confirm exact dates each year
A9: E0008 | B9: Onam celebrations | C9: D204 | D9: =IFERROR(INDEX(Destination!$B$2:$B$501,MATCH(C9,Destination!$A$2:$A$501,0)),"") -> Thiruvananthapuram | F9: =INDEX(Destination!$F$2:$F$501,MATCH(C9,Destination!$A$2:$A$501,0)) -> 8.52 | G9: =INDEX(Destination!$G$2:$G$501,MATCH(C9,Destination!$A$2:$A$501,0)) -> 76.94 | H9: Aug–Sep | K9: 10 | L9: Festival | M9: Medium – typical timing; confirm exact dates each year
A10: E0009 | B10: Nehru Trophy Boat Race | C10: D198 | D10: =IFERROR(INDEX(Destination!$B$2:$B$501,MATCH(C10,Destination!$A$2:$A$501,0)),"") -> Alleppey | E10: Punnamada Lake | F10: =INDEX(Destination!$F$2:$F$501,MATCH(C10,Destination!$A$2:$A$501,0)) -> 9.49 | G10: =INDEX(Destination!$G$2:$G$501,MATCH(C10,Destination!$A$2:$A$501,0)) -> 76.34 | H10: Aug | K10: 1 | L10: Sport | M10: Medium – typical timing; confirm exact dates each year
A11: E0010 | B11: Durga Puja | C11: D271 | D11: =IFERROR(INDEX(Destination!$B$2:$B$501,MATCH(C11,Destination!$A$2:$A$501,0)),"") -> Kolkata | F11: =INDEX(Destination!$F$2:$F$501,MATCH(C11,Destination!$A$2:$A$501,0)) -> 22.57 | G11: =INDEX(Destination!$G$2:$G$501,MATCH(C11,Destination!$A$2:$A$501,0)) -> 88.36 | H11: Sep–Oct | K11: 5 | L11: Religious | M11: Medium – typical timing; confirm exact dates each year
A12: E0011 | B12: Ganesh Chaturthi | C12: D096 | D12: =IFERROR(INDEX(Destination!$B$2:$B$501,MATCH(C12,Destination!$A$2:$A$501,0)),"") -> Mumbai | F12: =INDEX(Destination!$F$2:$F$501,MATCH(C12,Destination!$A$2:$A$501,0)) -> 19.08 | G12: =INDEX(Destination!$G$2:$G$501,MATCH(C12,Destination!$A$2:$A$501,0)) -> 72.88 | H12: Aug–Sep | K12: 10 | L12: Religious | M12: Medium – typical timing; confirm exact dates each year
A13: E0012 | B13: Konark Dance Festival | C13: D258 | D13: =IFERROR(INDEX(Destination!$B$2:$B$501,MATCH(C13,Destination!$A$2:$A$501,0)),"") -> Konark | E13: Konark Sun Temple area | F13: =INDEX(Destination!$F$2:$F$501,MATCH(C13,Destination!$A$2:$A$501,0)) -> 19.89 | G13: =INDEX(Destination!$G$2:$G$501,MATCH(C13,Destination!$A$2:$A$501,0)) -> 86.09 | H13: Dec | K13: 5 | L13: Cultural | M13: Medium – typical timing; confirm exact dates each year
A14: E0013 | B14: Khajuraho Dance Festival | C14: D018 | D14: =IFERROR(INDEX(Destination!$B$2:$B$501,MATCH(C14,Destination!$A$2:$A$501,0)),"") -> Khajuraho | E14: Khajuraho temples | F14: =INDEX(Destination!$F$2:$F$501,MATCH(C14,Destination!$A$2:$A$501,0)) -> 24.85 | G14: =INDEX(Destination!$G$2:$G$501,MATCH(C14,Destination!$A$2:$A$501,0)) -> 79.92 | H14: Feb | K14: 7 | L14: Cultural | M14: Medium – typical timing; confirm exact dates each year
A15: E0014 | B15: Goa Carnival | C15: D121 | D15: =IFERROR(INDEX(Destination!$B$2:$B$501,MATCH(C15,Destination!$A$2:$A$501,0)),"") -> Panaji | F15: =INDEX(Destination!$F$2:$F$501,MATCH(C15,Destination!$A$2:$A$501,0)) -> 15.5 | G15: =INDEX(Destination!$G$2:$G$501,MATCH(C15,Destination!$A$2:$A$501,0)) -> 73.83 | H15: Feb–Mar | K15: 4 | L15: Festival | M15: Medium – typical timing; confirm exact dates each year
A16: E0015 | B16: Hemis Festival | C16: D398 | D16: =IFERROR(INDEX(Destination!$B$2:$B$501,MATCH(C16,Destination!$A$2:$A$501,0)),"") -> Hemis | E16: Hemis Monastery | F16: =INDEX(Destination!$F$2:$F$501,MATCH(C16,Destination!$A$2:$A$501,0)) -> 33.91 | G16: =INDEX(Destination!$G$2:$G$501,MATCH(C16,Destination!$A$2:$A$501,0)) -> 77.7 | H16: Jun–Jul | K16: 2 | L16: Religious | M16: Medium – typical timing; confirm exact dates each year
A17: E0016 | B17: Rann Utsav | C17: D083 | D17: =IFERROR(INDEX(Destination!$B$2:$B$501,MATCH(C17,Destination!$A$2:$A$501,0)),"") -> Kutch | E17: Dhordo (White Rann) | F17: =INDEX(Destination!$F$2:$F$501,MATCH(C17,Destination!$A$2:$A$501,0)) -> 23.5 | G17: =INDEX(Destination!$G$2:$G$501,MATCH(C17,Destination!$A$2:$A$501,0)) -> 69.8 | H17: Nov–Feb | K17: 100 | L17: Cultural | M17: Medium – typical timing; confirm exact dates each year
A18: E0017 | B18: International Kite Festival | C18: D076 | D18: =IFERROR(INDEX(Destination!$B$2:$B$501,MATCH(C18,Destination!$A$2:$A$501,0)),"") -> Ahmedabad | F18: =INDEX(Destination!$F$2:$F$501,MATCH(C18,Destination!$A$2:$A$501,0)) -> 23.02 | G18: =INDEX(Destination!$G$2:$G$501,MATCH(C18,Destination!$A$2:$A$501,0)) -> 72.57 | H18: Jan | K18: 7 | L18: Festival | M18: Medium – typical timing; confirm exact dates each year
A19: E0018 | B19: Taj Mahotsav | C19: D001 | D19: =IFERROR(INDEX(Destination!$B$2:$B$501,MATCH(C19,Destination!$A$2:$A$501,0)),"") -> Agra | E19: Shilpgram | F19: =INDEX(Destination!$F$2:$F$501,MATCH(C19,Destination!$A$2:$A$501,0)) -> 27.18 | G19: =INDEX(Destination!$G$2:$G$501,MATCH(C19,Destination!$A$2:$A$501,0)) -> 78.02 | H19: Feb | K19: 10 | L19: Cultural | M19: Medium – typical timing; confirm exact dates each year
A20: E0019 | B20: Desert Festival | C20: D049 | D20: =IFERROR(INDEX(Destination!$B$2:$B$501,MATCH(C20,Destination!$A$2:$A$501,0)),"") -> Jaisalmer | F20: =INDEX(Destination!$F$2:$F$501,MATCH(C20,Destination!$A$2:$A$501,0)) -> 26.92 | G20: =INDEX(Destination!$G$2:$G$501,MATCH(C20,Destination!$A$2:$A$501,0)) -> 70.91 | H20: Feb | K20: 3 | L20: Cultural | M20: Medium – typical timing; confirm exact dates each year
A21: E0020 | B21: Sangai Festival | C21: D356 | D21: =IFERROR(INDEX(Destination!$B$2:$B$501,MATCH(C21,Destination!$A$2:$A$501,0)),"") -> Imphal | F21: =INDEX(Destination!$F$2:$F$501,MATCH(C21,Destination!$A$2:$A$501,0)) -> 24.82 | G21: =INDEX(Destination!$G$2:$G$501,MATCH(C21,Destination!$A$2:$A$501,0)) -> 93.94 | H21: Nov | K21: 10 | L21: Cultural | M21: Medium – typical timing; confirm exact dates each year
A22: E0021 | B22: Ziro Festival of Music | C22: D344 | D22: =IFERROR(INDEX(Destination!$B$2:$B$501,MATCH(C22,Destination!$A$2:$A$501,0)),"") -> Ziro | F22: =INDEX(Destination!$F$2:$F$501,MATCH(C22,Destination!$A$2:$A$501,0)) -> 27.55 | G22: =INDEX(Destination!$G$2:$G$501,MATCH(C22,Destination!$A$2:$A$501,0)) -> 93.83 | H22: Sep | K22: 4 | L22: Music | M22: Medium – typical timing; confirm exact dates each year
A23: E0022 | B23: Ayodhya Deepotsav | C23: D429 | D23: =IFERROR(INDEX(Destination!$B$2:$B$501,MATCH(C23,Destination!$A$2:$A$501,0)),"") -> Ayodhya | E23: Ram ki Paidi / Saryu ghats | F23: =INDEX(Destination!$F$2:$F$501,MATCH(C23,Destination!$A$2:$A$501,0)) -> 26.8 | G23: =INDEX(Destination!$G$2:$G$501,MATCH(C23,Destination!$A$2:$A$501,0)) -> 82.2 | H23: Oct–Nov | K23: 1 | L23: Religious | M23: Medium – typical timing; confirm exact dates each year
A24: E0023 | B24: Madurai Chithirai Festival | C24: D167 | D24: =IFERROR(INDEX(Destination!$B$2:$B$501,MATCH(C24,Destination!$A$2:$A$501,0)),"") -> Madurai | E24: Meenakshi Amman Temple | F24: =INDEX(Destination!$F$2:$F$501,MATCH(C24,Destination!$A$2:$A$501,0)) -> 9.93 | G24: =INDEX(Destination!$G$2:$G$501,MATCH(C24,Destination!$A$2:$A$501,0)) -> 78.12 | H24: Apr–May | K24: 12 | L24: Religious | M24: Medium – typical timing; confirm exact dates each year
A25: E0024 | B25: Chennai Margazhi Music Season | C25: D164 | D25: =IFERROR(INDEX(Destination!$B$2:$B$501,MATCH(C25,Destination!$A$2:$A$501,0)),"") -> Chennai | F25: =INDEX(Destination!$F$2:$F$501,MATCH(C25,Destination!$A$2:$A$501,0)) -> 13.08 | G25: =INDEX(Destination!$G$2:$G$501,MATCH(C25,Destination!$A$2:$A$501,0)) -> 80.27 | H25: Dec–Jan | K25: 30 | L25: Music | M25: Medium – typical timing; confirm exact dates each year
A26: E0025 | B26: Kullu Dussehra | C26: D381 | D26: =IFERROR(INDEX(Destination!$B$2:$B$501,MATCH(C26,Destination!$A$2:$A$501,0)),"") -> Kullu | E26: Dhalpur Maidan | F26: =INDEX(Destination!$F$2:$F$501,MATCH(C26,Destination!$A$2:$A$501,0)) -> 31.96 | G26: =INDEX(Destination!$G$2:$G$501,MATCH(C26,Destination!$A$2:$A$501,0)) -> 77.11 | H26: Oct | K26: 7 | L26: Festival | M26: Medium – typical timing; confirm exact dates each year
A27: E0026 | B27: International Yoga Festival | C27: D027 | D27: =IFERROR(INDEX(Destination!$B$2:$B$501,MATCH(C27,Destination!$A$2:$A$501,0)),"") -> Rishikesh | F27: =INDEX(Destination!$F$2:$F$501,MATCH(C27,Destination!$A$2:$A$501,0)) -> 30.09 | G27: =INDEX(Destination!$G$2:$G$501,MATCH(C27,Destination!$A$2:$A$501,0)) -> 78.27 | H27: Mar | K27: 7 | L27: Cultural | M27: Medium – typical timing; confirm exact dates each year
A28: E0027 | B28: Bikaner Camel Festival | C28: D052 | D28: =IFERROR(INDEX(Destination!$B$2:$B$501,MATCH(C28,Destination!$A$2:$A$501,0)),"") -> Bikaner | F28: =INDEX(Destination!$F$2:$F$501,MATCH(C28,Destination!$A$2:$A$501,0)) -> 28.02 | G28: =INDEX(Destination!$G$2:$G$501,MATCH(C28,Destination!$A$2:$A$501,0)) -> 73.31 | H28: Jan | K28: 2 | L28: Festival | M28: Medium – typical timing; confirm exact dates each year
A29: E0028 | B29: Mewar Festival | C29: D048 | D29: =IFERROR(INDEX(Destination!$B$2:$B$501,MATCH(C29,Destination!$A$2:$A$501,0)),"") -> Udaipur | F29: =INDEX(Destination!$F$2:$F$501,MATCH(C29,Destination!$A$2:$A$501,0)) -> 24.58 | G29: =INDEX(Destination!$G$2:$G$501,MATCH(C29,Destination!$A$2:$A$501,0)) -> 73.68 | H29: Mar–Apr | K29: 3 | L29: Festival | M29: Medium – typical timing; confirm exact dates each year
A30: E0029 | B30: Rajasthan International Folk Festival | C30: D047 | D30: =IFERROR(INDEX(Destination!$B$2:$B$501,MATCH(C30,Destination!$A$2:$A$501,0)),"") -> Jodhpur | E30: Mehrangarh Fort | F30: =INDEX(Destination!$F$2:$F$501,MATCH(C30,Destination!$A$2:$A$501,0)) -> 26.3 | G30: =INDEX(Destination!$G$2:$G$501,MATCH(C30,Destination!$A$2:$A$501,0)) -> 73.02 | H30: Oct | K30: 5 | L30: Music | M30: Medium – typical timing; confirm exact dates each year

Sheet Booking
A1: booking_id | B1: trip_id | C1: item_type | D1: item_id | E1: booked_at | F1: start_time | G1: end_time | H1: cost_inr | I1: status | J1: confirmation_ref
A2: EXAMPLE | B2: TRIP-001 | C2: Hotel | D2: H0001 | E2: 2026-10-01 10:30 | F2: 2026-11-05 14:00 | G2: 2026-11-07 11:00 | H2: 18000 | I2: Confirmed | J2: ABC123

Sheet Trip
A1: trip_id | B1: trip_name | C1: traveller_count | D1: start_date | E1: end_date | F1: budget_inr | G1: budget_style | H1: preferences (interests) | I1: origin_dest_id | J1: dest_ids (visited) | K1: notes
A2: EXAMPLE | B2: Golden Triangle – delete this row | C2: 2 | D2: 2026-11-05 | E2: 2026-11-10 | F2: 60000 | G2: Mid-range | H2: Heritage, Food | I2: D400 | J2: D001, D002 | K2: Interests use the same tags as Activity sheet

Sheet Assumptions
A1: assumption | B1: value | C1: unit | D1: note
A2: Earth radius | B2: 6371 | C2: km | D2: Mean Earth radius used in the haversine (straight-line) distance formula
A3: Road circuity factor | B3: 1.3 | C3: x | D3: ASSUMPTION: road distance ≈ straight-line × 1.3. Mountain/coastal routes are usually higher (1.5–2.0)
A4: Average road speed | B4: 45 | C4: km/h | D4: ASSUMPTION: blended average speed for intercity roads in India; hill routes are slower
A6: Blue text on yellow = editable assumption. TransportRoute recalculates when these change.
